Workbook

Sheet 首页仪表盘
A1: 氧化加工厂经营仪表盘
A2: 截至：2025年5月31日
A4: 本月营业收入 | C4: 本月费用支出 | E4: 本月净利润 | G4: G银行余额
A6: =SUMIF(加工订单!A:A,"2025-05*",加工订单!I:I) | C6: =SUMIF(费用明细!E:E,"2025-05",费用明细!C:C) | E6: =A6-C6 | G6: =G银行!F35
A8: N银行/微信余额 | C8: 应收账款合计
A10: =N银行微信!F55 | C10: =SUMIF(应收应付!D3:D11,">0",应收应付!D3:D11)
A12: [!] 库存预警
A13: 材料名称 | B13: 期末库存 | C13: 安全库存 | D13: 预警状态
A14: 硫酸 | B14: =材料库存!G3 | C14: =材料库存!H3 | D14: =材料库存!I3
A15: 硝酸 | B15: =材料库存!G4 | C15: =材料库存!H4 | D15: =材料库存!I4
A16: 铬酸 | B16: =材料库存!G5 | C16: =材料库存!H5 | D16: =材料库存!I5
A17: 片碱 | B17: =材料库存!G6 | C17: =材料库存!H6 | D17: =材料库存!I6
A18: 亚硝酸钠 | B18: =材料库存!G7 | C18: =材料库存!H7 | D18: =材料库存!I7
A19: 黑色色粉 | B19: =材料库存!G8 | C19: =材料库存!H8 | D19: =材料库存!I8
A20: 银白色色粉 | B20: =材料库存!G9 | C20: =材料库存!H9 | D20: =材料库存!I9
A21: 香槟色色粉 | B21: =材料库存!G10 | C21: =材料库存!H10 | D21: =材料库存!I10
A22: 蓝色色粉 | B22: =材料库存!G11 | C22: =材料库存!H11 | D22: =材料库存!I11
A23: 除油剂 | B23: =材料库存!G12 | C23: =材料库存!H12 | D23: =材料库存!I12
A24: 挂具 | B24: =材料库存!G13 | C24: =材料库存!H13 | D24: =材料库存!I13
A26: [!] 欠款提醒 - 应收余额>0的客户
A27: 客户名称 | B27: 订单总金额 | C27: 已收金额 | D27: 应收余额
A28: 永达五金厂 | B28: =应收应付!B3 | C28: =应收应付!C3 | D28: =应收应付!D3
A29: 恒丰铝业 | B29: =应收应付!B4 | C29: =应收应付!C4 | D29: =应收应付!D4
A30: 鑫达精密 | B30: =应收应付!B5 | C30: =应收应付!C5 | D30: =应收应付!D5
A31: 华泰金属 | B31: =应收应付!B6 | C31: =应收应付!C6 | D31: =应收应付!D6
A32: 博远五金 | B32: =应收应付!B7 | C32: =应收应付!C7 | D32: =应收应付!D7
A33: 天成铝材 | B33: =应收应付!B8 | C33: =应收应付!C8 | D33: =应收应付!D8
A34: 宏盛五金 | B34: =应收应付!B9 | C34: =应收应付!C9 | D34: =应收应付!D9
A35: 瑞丰金属 | B35: =应收应付!B10 | C35: =应收应付!C10 | D35: =应收应付!D10
A37: [!] 进行中的订单
A38: 订单号 | B38: 客户 | C38: 产品名称 | D38: 数量 | E38: 单位 | F38: 金额 | G38: 日期 | H38: 状态
A39: DD20250317003 | B39: 永达五金厂 | C39: 铝件抛光+氧化 | D39: 1446 | E39: 件 | F39: 4512.67 | G39: 2025-03-17 | H39: 进行中
A40: DD20250309007 | B40: 永达五金厂 | C40: 铝件喷砂(委外) | D40: 1096 | E40: 件 | F40: 1799.56 | G40: 2025-03-09 | H40: 进行中
A41: DD20250326019 | B41: 宏盛五金 | C41: 铝件氧化-香槟 | D41: 800 | E41: kg | F41: 3669.04 | G41: 2025-03-26 | H41: 进行中
A42: DD20250325021 | B42: 博远五金 | C42: 铝型材氧化-银白 | D42: 268 | E42: m | F42: 581.91 | G42: 2025-03-25 | H42: 进行中
A43: DD20250413006 | B43: 永达五金厂 | C43: 铝件抛光(委外) | D43: 484 | E43: 件 | F43: 1029.29 | G43: 2025-04-13 | H43: 进行中
A44: DD20250412007 | B44: 博远五金 | C44: 铜件氧化 | D44: 485 | E44: 件 | F44: 750.78 | G44: 2025-04-12 | H44: 进行中
A45: DD20250413015 | B45: 博远五金 | C45: 铝件喷砂+氧化 | D45: 424 | E45: 件 | F45: 875.97 | G45: 2025-04-13 | H45: 进行中
A46: DD20250402021 | B46: 华泰金属 | C46: 铝件抛光(委外) | D46: 1242 | E46: 件 | F46: 2617.39 | G46: 2025-04-02 | H46: 进行中
A47: DD20250509001 | B47: 天成铝材 | C47: 铜件氧化 | D47: 1670 | E47: 件 | F47: 2297.92 | G47: 2025-05-09 | H47: 进行中
...

Sheet 使用说明
A1: 氧化加工厂管理系统 V15.0 - 使用说明
A3: 【业务流程】
A4: 客户来料 -> 喷砂/拉丝/抛光(可委外) -> 氧化(最终工序) -> 完工 -> 收取加工费
A6: 【计价方式】支持6种：按件、按条、按只、按个、按米长、按米重、按平方
A8: 【收付款方式】
A9: 客户付款不与订单一一对应，按实际发生记录
A10: 付供应商也不一一对应，按实际发生记录
A11: G银行 = 有票（对公账户，大部分收支走这里）
A12: N银行/微信 = 当现金用（零星收支）
A14: 【费用科目】
A15: 房租、水电费、三酸(硫酸/硝酸/铬酸)、片碱、亚硝酸钠、色粉、除油剂、挂具、外发加工费、工资、日常费用
A17: 【小会计操作指南】
... A80: 应收应付 - 客户/供应商欠款汇总+账龄分析

Sheet 基础设置
A1: 【客户信息】
A2: 客户名称 | B2: 联系人 | C2: 电话 | D2: 结算方式
A3: 永达五金厂 | B3: 陈总 | C3: 13900001111 | D3: 月结30天
A4: 恒丰铝业 | B4: 林经理 | C4: 13900002222 | D4: 月结30天
A5: 鑫达精密 | B5: 王总 | C5: 13900003333 | D5: 月结15天
A6: 华泰金属 | B6: 赵经理 | C6: 13900004444 | D6: 现结
A7: 博远五金 | B7: 刘总 | C7: 13900005555 | D7: 月结30天
A8: 天成铝材 | B8: 张经理 | C8: 13900006666 | D8: 月结15天
A9: 宏盛五金 | B9: 周总 | C9: 13900007777 | D9: 月结30天
A10: 瑞丰金属 | B10: 吴经理 | C10: 13900008888 | D10: 现结
A12: 【供应商信息】
A13: 供应商名称 | B13: 供应范围 | C13: 结算方式
A14: XX化工 | B14: 三酸/片碱/亚钠 | C14: 月结
A15: YY化工 | B15: 色粉/除油剂 | C15: 月结
A16: ZZ挂具厂 | B16: 挂具 | C16: 现结
A17: AA喷砂厂 | B17: 喷砂委外加工 | C17: 月结
A18: BB抛光厂 | B18: 抛光委外加工 | C18: 月结
A20: 【员工信息】
A21: 姓名 | B21: 部门 | C21: 岗位 | D21: 基本工资
A22: 张三 | B22: 生产部 | C22: 操作工 | D22: 3800
A23: 李四 | B23: 生产部 | C23: 操作工 | D23: 4000
A24: 王五 | B24: 生产部 | C24: 班长 | D24: 4500
A25: 赵六 | B25: 生产部 | C25: 操作工 | D25: 3800
A26: 陈七 | B26: 管理部 | C26: 会计 | D26: 5000
A27: 刘八 | B27: 管理部 | C27: 老板 | D27: 8000
A29: 【产品与计价】
A30: 产品名称 | B30: 工序 | C30: 计价方式 | D30: 单位 | E30: 参考单价(元)
A31: 铝件氧化-银白 | B31: 氧化 | C31: 按米重 | D31: kg | E31: 3.5
A32: 铝件氧化-黑色 | B32: 氧化 | C32: 按米重 | D32: kg | E32: 4
A33: 铝件氧化-香槟 | B33: 氧化 | C33: 按米重 | D33: kg | E33: 4.5
A34: 铝件氧化-蓝色 | B34: 氧化 | C34: 按米重 | D34: kg | E34: 5
A35: 铝件喷砂+氧化 | B35: 喷砂+氧化 | C35: 按件 | D35: 件 | E35: 2
A36: 铝件拉丝+氧化 | B36: 拉丝+氧化 | C36: 按件 | D36: 件 | E36: 2.5
A37: 铝件抛光+氧化 | B37: 抛光+氧化 | C37: 按件 | D37: 件 | E37: 3
A38: 铜件氧化 | B38: 氧化 | C38: 按件 | D38: 件 | E38: 1.5
A39: 铝板氧化 | B39: 氧化 | C39: 按平方 | D39: ㎡ | E39: 25
A40: 铝管氧化 | B40: 氧化 | C40: 按米长 | D40: m | E40: 1.8
A41: 铝型材氧化-银白 | B41: 氧化 | C41: 按米长 | D41: m | E41: 2.2
A42: 铝型材氧化-黑色 | B42: 氧化 | C42: 按米长 | D42: m | E42: 2.8
... A46: 铝件抛光(委外) | B46: 抛光(委外) | C46: 按件 | D46: 件 | E46: 2

Sheet 加工订单
A1: 日期 | B1: 订单号 | C1: 客户 | D1: 产品名称 | E1: 计价方式 | F1: 数量 | G1: 单位 | H1: 单价 | I1: 金额(不含税) | J1: 税额(13%) | K1: 价税合计 | L1: 状态
A2: 2025-03-04 | B2: DD20250304001 | C2: 永达五金厂 | D2: 铝板氧化 | E2: 按平方 | F2: 528 | G2: ㎡ | H2: 23.2 | I2: 12248.38 | J2: 1592.29 | K2: 13840.67 | L2: 已完成
A3: 2025-03-22 | B3: DD20250322002 | C3: 恒丰铝业 | D3: 铝外壳氧化 | E3: 按个 | F3: 112 | G3: 个 | H3: 1.1 | I3: 123.48 | J3: 16.05 | K3: 139.53 | L3: 已完成
A4: 2025-03-17 | B4: DD20250317003 | C4: 永达五金厂 | D4: 铝件抛光+氧化 | E4: 按件 | F4: 1446 | G4: 件 | H4: 3.12 | I4: 4512.67 | J4: 586.65 | K4: 5099.32 | L4: 进行中
A5: 2025-03-08 | B5: DD20250308004 | C5: 瑞丰金属 | D5: 铝板氧化 | E5: 按平方 | F5: 1628 | G5: ㎡ | H5: 22.53 | I5: 36682.9 | J5: 4768.78 | K5: 41451.68 | L5: 已完成
A6: 2025-03-23 | B6: DD20250323005 | C6: 宏盛五金 | D6: 铝型材氧化-银白 | E6: 按米长 | F6: 592 | G6: m | H6: 2.07 | I6: 1228.24 | J6: 159.67 | K6: 1387.91 | L6: 已完成
A7: 2025-03-04 | B7: DD20250304006 | C7: 恒丰铝业 | D7: 铝散热器氧化 | E7: 按只 | F7: 239 | G7: 只 | H7: 0.86 | I7: 204.49 | J7: 26.58 | K7: 231.07 | L7: 待加工
A8: 2025-03-09 | B8: DD20250309007 | C8: 永达五金厂 | D8: 铝件喷砂(委外) | E8: 按件 | F8: 1096 | G8: 件 | H8: 1.64 | I8: 1799.56 | J8: 233.94 | K8: 2033.5 | L8: 进行中
A9: 2025-03-03 | B9: DD20250303008 | C9: 博远五金 | D9: 铝型材氧化-黑色 | E9: 按米长 | F9: 1176 | G9: m | H9: 2.91 | I9: 3427.52 | J9: 445.58 | K9: 3873.1 | L9: 已完成
A10: 2025-03-22 | B10: DD20250322009 | C10: 华泰金属 | D10: 铝管氧化 | E10: 按米长 | F10: 1971 | G10: m | H10: 1.93 | I10: 3799.92 | J10: 493.99 | K10: 4293.91 | L10: 已完成
A11: 2025-03-13 | B11: DD20250313010 | C11: 博远五金 | D11: 铝件喷砂(委外) | E11: 按件 | F11: 1290 | G11: 件 | H11: 1.46 | I11: 1882.69 | J11: 244.75 | K11: 2127.44 | L11: 已完成
A12: 2025-03-12 | B12: DD20250312011 | C12: 华泰金属 | D12: 铝板氧化 | E12: 按平方 | F12: 1419 | G12: ㎡ | H12: 25.92 | I12: 36777.27 | J12: 4781.05 | K12: 41558.32 | L12: 已完成
A13: 2025-03-20 | B13: DD20250320012 | C13: 鑫达精密 | D13: 铜件氧化 | E13: 按件 | F13: 369 | G13: 件 | H13: 1.46 | I13: 540.16 | J13: 70.22 | K13: 610.38 | L13: 待加工
... A74: 2025-05-14 | B74: DD20250514024 | C74: 恒丰铝业 | D74: 铜件氧化 | E74: 按件 | F74: 1313 | G74: 件 | H74: 1.62 | I74: 2130.37 | J74: 276.95 | K74: 2407.32 | L74: 已完成
A76: (新增数据请在此行下方添加) | B76: =IF(A3="","",TEXT(A3,"DDyyyymmdd")&TEXT(ROW(),"000"))

Sheet 生产进度跟踪
A1: 生产进度跟踪
A2: 跟踪每笔订单从来料到出货的全流程
A3: 订单号 | B3: 客户 | C3: 产品 | D3: 数量 | E3: 来料日期 | F3: 喷砂状态 | G3: 喷砂完成日 | H3: 氧化状态 | I3: 氧化完成日 | J3: 出货状态 | K3: 出货日期 | L3: 备注
A4: DD20250304001 | B4: 永达五金厂 | C4: 铝板氧化 | D4: 528 | E4: 2025-03-04 | F4: 已完成 | G4: 2025-03-06 | H4: 已完成 | I4: 2025-03-09 | J4: 已出货 | K4: 2025-03-11
A5: DD20250322002 | B5: 恒丰铝业 | C5: 铝外壳氧化 | D5: 112 | E5: 2025-03-22 | F5: 已完成 | G5: 2025-03-24 | H5: 已完成 | I5: 2025-03-27 | J5: 已出货 | K5: 2025-03-28
A6: DD20250308004 | B6: 瑞丰金属 | C6: 铝板氧化 | D6: 1628 | E6: 2025-03-08 | F6: 已完成 | G6: 2025-03-10 | H6: 已完成 | I6: 2025-03-13 | J6: 已出货 | K6: 2025-03-15
A7: DD20250323005 | B7: 宏盛五金 | C7: 铝型材氧化-银白 | D7: 592 | E7: 2025-03-23 | F7: 已完成 | G7: 2025-03-25 | H7: 已完成 | I7: 2025-03-28 | J7: 已出货 | K7: 2025-03-28
A8: DD20250303008 | B8: 博远五金 | C8: 铝型材氧化-黑色 | D8: 1176 | E8: 2025-03-03 | F8: 已完成 | G8: 2025-03-05 | H8: 已完成 | I8: 2025-03-08 | J8: 已出货 | K8: 2025-03-10
A9: DD20250317003 | B9: 永达五金厂 | C9: 铝件抛光+氧化 | D9: 1446 | E9: 2025-03-17 | F9: 已完成 | G9: 2025-03-19 | H9: 进行中 | J9: 未开始 | L9: 待氧化完成
A10: DD20250309007 | B10: 永达五金厂 | C10: 铝件喷砂(委外) | D10: 1096 | E10: 2025-03-09 | F10: 已完成 | G10: 2025-03-11 | H10: 进行中 | J10: 未开始 | L10: 待氧化完成
A11: DD20250326019 | B11: 宏盛五金 | C11: 铝件氧化-香槟 | D11: 800 | E11: 2025-03-26 | F11: 已完成 | G11: 2025-03-28 | H11: 进行中 | J11: 未开始 | L11: 待氧化完成
A12: DD20250325021 | B12: 博远五金 | C12: 铝型材氧化-银白 | D12: 268 | E12: 2025-03-25 | F12: 已完成 | G12: 2025-03-27 | H12: 进行中 | J12: 未开始 | L12: 待氧化完成
A13: DD20250413006 | B13: 永达五金厂 | C13: 铝件抛光(委外) | D13: 484 | E13: 2025-04-13 | F13: 已完成 | G13: 2025-04-15 | H13: 进行中 | J13: 未开始 | L13: 待氧化完成

Sheet 收款记录
A1: 日期 | B1: 单据号 | C1: 客户名称 | D1: 收款金额(元) | E1: 收款方式 | F1: 摘要 | G1: 关联订单号 | H1: 结算状态 | I1: 核销日期 | J1: 备注
A2: 2025-03-27 | B2: SK20250327884 | C2: 恒丰铝业 | D2: 19603.72 | E2: 微信收款 | F2: 收恒丰铝业加工费 | G2: GD20250327125 | H2: 未核销
A3: 2025-03-05 | B3: SK20250305269 | C3: 鑫达精密 | D3: 13875.51 | E3: 微信收款 | F3: 收鑫达精密加工费 | H3: 已核销 | I3: 2025-03-17
A4: 2025-03-09 | B4: SK20250309873 | C4: 宏盛五金 | D4: 19358.53 | E4: 微信收款 | F4: 收宏盛五金加工费 | H4: 已核销 | I4: 2025-03-19
A5: 2025-03-24 | B5: SK20250324787 | C5: 华泰金属 | D5: 14833.08 | E5: 微信收款 | F5: 收华泰金属加工费 | G5: GD20250324130 | H5: 已核销 | I5: 2025-03-28
A6: 2025-03-21 | B6: SK20250321562 | C6: 天成铝材 | D6: 9885.8 | E6: 微信收款 | F6: 收天成铝材加工费 | H6: 已核销 | I6: 2025-03-30
A7: 2025-03-04 | B7: SK20250304121 | C7: 华泰金属 | D7: 6044.55 | E7: N银行转账 | F7: 收华泰金属加工费 | H7: 未核销
A8: 2025-03-19 | B8: SK20250319172 | C8: 华泰金属 | D8: 12591.92 | E8: G银行转账 | F8: 收华泰金属加工费 | H8: 未核销
A9: 2025-03-23 | B9: SK20250323980 | C9: 永达五金厂 | D9: 6120.95 | E9: G银行转账 | F9: 收永达五金厂加工费 | G9: GD20250323106 | H9: 已核销 | I9: 2025-04-04
A10: 2025-03-11 | B10: SK20250311785 | C10: 恒丰铝业 | D10: 11254.81 | E10: N银行转账 | F10: 收恒丰铝业加工费 | G10: GD20250311384 | H10: 已核销 | I10: 2025-03-15
A11: 2025-03-16 | B11: SK20250316690 | C11: 华泰金属 | D11: 11706.21 | E11: 微信收款 | F11: 收华泰金属加工费 | G11: GD20250316444 | H11: 已核销 | I11: 2025-03-18
A12: 2025-03-16 | B12: SK20250316294 | C12: 华泰金属 | D12: 16123.15 | E12: 微信收款 | F12: 收华泰金属加工费 | H12: 未核销
A13: 2025-03-04 | B13: SK20250304533 | C13: 恒丰铝业 | D13: 13861.69 | E13: N银行转账 | F13: 收恒丰铝业加工费 | G13: GD20250304718 | H13: 未核销
A14: 2025-03-14 | B14: SK20250314789 | C14: 瑞丰金属 | D14: 17549.06 | E14: G银行转账 | F14: 收瑞丰金属加工费 | G14: GD20250314847 | H14: 未核销
A15: 2025-03-21 | B15: SK20250321919 | C15: 恒丰铝业 | D15: 3091.03 | E15: N银行转账 | F15: 收恒丰铝业加工费 | G15: GD20250321487 | H15: 已核销 | I15: 2025-03-30
A16: 2025-03-28 | B16: SK20250328649 | C16: 恒丰铝业 | D16: 6475.81 | E16: G银行转账 | F16: 收恒丰铝业加工费 | H16: 未核销
A17: 2025-04-22 | B17: SK20250422727 | C17: 天成铝材 | D17: 19100.71 | E17: 微信收款 | F17: 收天成铝材加工费 | G17: GD20250422821 | H17: 已核销 | I17: 2025-04-23
A18: 2025-04-27 | B18: SK20250427556 | C18: 宏盛五金 | D18: 16950.25 | E18: 微信收款 | F18: 收宏盛五金加工费 | G18: GD20250427891 | H18: 未核销
A19: 2025-04-06 | B19: SK20250406960 | C19: 瑞丰金属 | D19: 10101.26 | E19: G银行转账 | F19: 收瑞丰金属加工费 | G19: GD20250406975 | H19: 已核销 | I19: 2025-04-20
A20: 2025-04-21 | B20: SK20250421596 | C20: 博远五金 | D20: 15784.65 | E20: 微信收款 | F20: 收博远五金加工费 | H20: 未核销
A21: 2025-04-21 | B21: SK20250421830 | C21: 华泰金属 | D21: 6942.75 | E21: G银行转账 | F21: 收华泰金属加工费 | G21: GD20250421954 | H21: 未核销
A22: 2025-04-10 | B22: SK20250410653 | C22: 华泰金属 | D22: 6890.87 | E22: N银行转账 | F22: 收华泰金属加工费 | H22: 未核销
A23: 2025-04-03 | B23: SK20250403810 | C23: 鑫达精密 | D23: 4714.95 | E23: 微信收款 | F23: 收鑫达精密加工费 | H23: 未核销
A24: 2025-04-05 | B24: SK20250405438 | C24: 华泰金属 | D24: 3156.12 | E24: 微信收款 | F24: 收华泰金属加工费 | G24: GD20250405799 | H24: 已核销 | I24: 2025-04-15
A25: 2025-04-18 | B25: SK20250418952 | C25: 瑞丰金属 | D25: 9483.94 | E25: G银行转账 | F25: 收瑞丰金属加工费 | G25: GD20250418646 | H25: 已核销 | I25: 2025-04-21
A26: 2025-04-14 | B26: SK20250414812 | C26: 宏盛五金 | D26: 18287.09 | E26: 微信收款 | F26: 收宏盛五金加工费 | G26: GD20250414376 | H26: 已核销 | I26: 2025-04-25
A27: 2025-04-01 | B27: SK20250401405 | C27: 宏盛五金 | D27: 10585.64 | E27: N银行转账 | F27: 收宏盛五金加工费 | H27: 已核销 | I27: 2025-04-05
A28: 2025-04-25 | B28: SK20250425651 | C28: 宏盛五金 | D28: 17362.06 | E28: 微信收款 | F28: 收宏盛五金加工费 | G28: GD20250425924 | H28: 未核销
A29: 2025-04-24 | B29: SK20250424546 | C29: 华泰金属 | D29: 10788.13 | E29: N银行转账 | F29: 收华泰金属加工费 | G29: GD20250424167 | H29: 已核销 | I29: 2025-05-09
A30: 2025-04-16 | B30: SK20250416841 | C30: 永达五金厂 | D30: 8999.43 | E30: 微信收款 | F30: 收永达五金厂加工费 | G30: GD20250416997 | H30: 未核销
A31: 2025-04-06 | B31: SK20250406646 | C31: 瑞丰金属 | D31: 18551.75 | E31: 微信收款 | F31: 收瑞丰金属加工费 | H31: 未核销
A32: 2025-05-02 | B32: SK20250502866 | C32: 鑫达精密 | D32: 16267.31 | E32: 微信收款 | F32: 收鑫达精密加工费 | H32: 未核销
A33: 2025-05-27 | B33: SK20250527805 | C33: 博远五金 | D33: 9904.76 | E33: 微信收款 | F33: 收博远五金加工费 | H33: 已核销 | I33: 2025-05-31
A34: 2025-05-10 | B34: SK20250510652 | C34: 宏盛五金 | D34: 18968.17 | E34: 微信收款 | F34: 收宏盛五金加工费 | G34: GD20250510651 | H34: 未核销
A35: 2025-05-16 | B35: SK20250516542 | C35: 瑞丰金属 | D35: 3447.95 | E35: G银行转账 | F35: 收瑞丰金属加工费 | G35: GD20250516538 | H35: 未核销
A36: 2025-05-24 | B36: SK20250524193 | C36: 天成铝材 | D36: 12866.85 | E36: G银行转账 | F36: 收天成铝材加工费 | H36: 已核销 | I36: 2025-06-02
A37: 2025-05-08 | B37: SK20250508690 | C37: 永达五金厂 | D37: 19992.3 | E37: N银行转账 | F37: 收永达五金厂加工费 | G37: GD20250508873 | H37: 已核销 | I37: 2025-05-22
A38: 2025-05-02 | B38: SK20250502384 | C38: 鑫达精密 | D38: 10469.01 | E38: 微信收款 | F38: 收鑫达精密加工费 | H38: 已核销 | I38: 2025-05-15
A39: 2025-05-06 | B39: SK20250506193 | C39: 宏盛五金 | D39: 13426.12 | E39: 微信收款 | F39: 收宏盛五金加工费 | G39: GD20250506710 | H39: 已核销 | I39: 2025-05-13
A40: 2025-05-16 | B40: SK20250516786 | C40: 天成铝材 | D40: 9350.27 | E40: N银行转账 | F40: 收天成铝材加工费 | H40: 未核销
...

Sheet 付款记录
A1: 日期 | B1: 单据号 | C1: 供应商/用途 | D1: 付款金额(元) | E1: 付款方式 | F1: 费用分类 | G1: 摘要 | H1: 关联发票号 | I1: 结算状态 | J1: 备注
A2: 2025-03-05 | B2: FK20250305355 | C2: AA喷砂厂 | D2: 3160.58 | E2: 微信付款 | F2: 外发加工费 | G2: 付AA喷砂厂喷砂委外加工 | I2: 已核销
A3: 2025-03-28 | B3: FK20250328200 | C3: XX化工 | D3: 6925.4 | E3: 现金 | F3: 材料费 | G3: 付XX化工三酸/片碱/亚钠 | H3: FP20250858 | I3: 已核销
A4: 2025-03-02 | B4: FK20250302871 | C4: BB抛光厂 | D4: 12622.4 | E4: G银行转账 | F4: 外发加工费 | G4: 付BB抛光厂抛光委外加工 | I4: 未核销
A5: 2025-03-28 | B5: FK20250328592 | C5: YY化工 | D5: 2911.51 | E5: 微信付款 | F5: 材料费 | G5: 付YY化工色粉/除油剂 | H5: FP20251153 | I5: 未核销
A6: 2025-03-07 | B6: FK20250307488 | C6: AA喷砂厂 | D6: 13585.42 | E6: G银行转账 | F6: 外发加工费 | G6: 付AA喷砂厂喷砂委外加工 | H6: FP20251221 | I6: 未核销
A7: 2025-03-01 | B7: FK20250301392 | C7: AA喷砂厂 | D7: 4345.44 | E7: 微信付款 | F7: 外发加工费 | G7: 付AA喷砂厂喷砂委外加工 | I7: 已核销
A8: 2025-03-14 | B8: FK20250314258 | C8: BB抛光厂 | D8: 10097.13 | E8: 微信付款 | F8: 外发加工费 | G8: 付BB抛光厂抛光委外加工 | H8: FP20250356 | I8: 未核销
A9: 2025-03-07 | B9: FK20250307693 | C9: ZZ挂具厂 | D9: 3656.66 | E9: G银行转账 | F9: 材料费 | G9: 付ZZ挂具厂挂具 | I9: 已核销
A10: 2025-03-24 | B10: FK20250324158 | C10: BB抛光厂 | D10: 1383.88 | E10: N银行转账 | F10: 外发加工费 | G10: 付BB抛光厂抛光委外加工 | H10: FP20251116 | I10: 已核销
A11: 2025-03-02 | B11: FK20250302261 | C11: BB抛光厂 | D11: 7413.43 | E11: 现金 | F11: 外发加工费 | G11: 付BB抛光厂抛光委外加工 | H11: FP20251138 | I11: 未核销
A12: 2025-03-02 | B12: FK20250302170 | C12: BB抛光厂 | D12: 1661.62 | E12: G银行转账 | F12: 外发加工费 | G12: 付BB抛光厂抛光委外加工 | H12: FP20250872 | I12: 已核销
A13: 2025-03-20 | B13: FK20250320513 | C13: XX化工 | D13: 10290.58 | E13: G银行转账 | F13: 材料费 | G13: 付XX化工三酸/片碱/亚钠 | I13: 已核销
A14: 2025-03-04 | B14: FK20250304140 | C14: BB抛光厂 | D14: 4070.12 | E14: 现金 | F14: 外发加工费 | G14: 付BB抛光厂抛光委外加工 | I14: 已核销
A15: 2025-03-20 | B15: FK20250320678 | C15: XX化工 | D15: 6578.76 | E15: 现金 | F15: 材料费 | G15: 付XX化工三酸/片碱/亚钠 | H15: FP20250707 | I15: 未核销
A16: 2025-03-17 | B16: FK20250317785 | C16: ZZ挂具厂 | D16: 14053.24 | E16: G银行转账 | F16: 材料费 | G16: 付ZZ挂具厂挂具 | H16: FP20251170 | I16: 已核销
A17: 2025-03-23 | B17: FK20250323234 | C17: ZZ挂具厂 | D17: 3960.95 | E17: 微信付款 | F17: 材料费 | G17: 付ZZ挂具厂挂具 | H17: FP20250226 | I17: 已核销
A18: 2025-03-22 | B18: FK20250322109 | C18: ZZ挂具厂 | D18: 7129.76 | E18: G银行转账 | F18: 材料费 | G18: 付ZZ挂具厂挂具 | H18: FP20251037 | I18: 未核销
A19: 2025-04-13 | B19: FK20250413185 | C19: BB抛光厂 | D19: 8683.68 | E19: G银行转账 | F19: 外发加工费 | G19: 付BB抛光厂抛光委外加工 | I19: 未核销
A20: 2025-04-21 | B20: FK20250421286 | C20: AA喷砂厂 | D20: 2467.64 | E20: 微信付款 | F20: 外发加工费 | G20: 付AA喷砂厂喷砂委外加工 | I20: 已核销
A21: 2025-04-02 | B21: FK20250402565 | C21: ZZ挂具厂 | D21: 5997.01 | E21: G银行转账 | F21: 材料费 | G21: 付ZZ挂具厂挂具 | H21: FP20250203 | I21: 未核销
A22: 2025-04-11 | B22: FK20250411384 | C22: ZZ挂具厂 | D22: 11537.83 | E22: 微信付款 | F22: 材料费 | G22: 付ZZ挂具厂挂具 | I22: 已核销
A23: 2025-04-25 | B23: FK20250425581 | C23: AA喷砂厂 | D23: 4157.94 | E23: G银行转账 | F23: 外发加工费 | G23: 付AA喷砂厂喷砂委外加工 | H23: FP20250245 | I23: 已核销
A24: 2025-04-01 | B24: FK20250401329 | C24: BB抛光厂 | D24: 1255.24 | E24: N银行转账 | F24: 外发加工费 | G24: 付BB抛光厂抛光委外加工 | I24: 未核销
A25: 2025-04-21 | B25: FK20250421872 | C25: XX化工 | D25: 11827.88 | E25: G银行转账 | F25: 材料费 | G25: 付XX化工三酸/片碱/亚钠 | H25: FP20250185 | I25: 未核销
A26: 2025-04-01 | B26: FK20250401736 | C26: YY化工 | D26: 3390.73 | E26: G银行转账 | F26: 材料费 | G26: 付YY化工色粉/除油剂 | H26: FP20250272 | I26: 未核销
A27: 2025-04-05 | B27: FK20250405677 | C27: YY化工 | D27: 2330.2 | E27: G银行转账 | F27: 材料费 | G27: 付YY化工色粉/除油剂 | I27: 已核销
A28: 2025-04-07 | B28: FK20250407271 | C28: AA喷砂厂 | D28: 10642.24 | E28: N银行转账 | F28: 外发加工费 | G28: 付AA喷砂厂喷砂委外加工 | H28: FP20250416 | I28: 未核销
A29: 2025-05-28 | B29: FK20250528395 | C29: YY化工 | D29: 5282.15 | E29: 微信付款 | F29: 材料费 | G29: 付YY化工色粉/除油剂 | I29: 未核销
A30: 2025-05-22 | B30: FK20250522137 | C30: AA喷砂厂 | D30: 12296.71 | E30: 现金 | F30: 外发加工费 | G30: 付AA喷砂厂喷砂委外加工 | I30: 已核销
A31: 2025-05-15 | B31: FK20250515218 | C31: XX化工 | D31: 5060.5 | E31: N银行转账 | F31: 材料费 | G31: 付XX化工三酸/片碱/亚钠 | I31: 已核销
A32: 2025-05-25 | B32: FK20250525773 | C32: AA喷砂厂 | D32: 13041.2 | E32: G银行转账 | F32: 外发加工费 | G32: 付AA喷砂厂喷砂委外加工 | H32: FP20250355 | I32: 已核销
A33: 2025-05-28 | B33: FK20250528292 | C33: BB抛光厂 | D33: 7198.66 | E33: G银行转账 | F33: 外发加工费 | G33: 付BB抛光厂抛光委外加工 | H33: FP20250792 | I33: 已核销
A34: 2025-05-17 | B34: FK20250517740 | C34: ZZ挂具厂 | D34: 9528.19 | E34: 微信付款 | F34: 材料费 | G34: 付ZZ挂具厂挂具 | H34: FP20251121 | I34: 未核销
A35: 2025-05-15 | B35: FK20250515234 | C35: XX化工 | D35: 3451.59 | E35: 现金 | F35: 材料费 | G35: 付XX化工三酸/片碱/亚钠 | H35: FP20251035 | I35: 未核销
A36: 2025-05-10 | B36: FK20250510224 | C36: AA喷砂厂 | D36: 13272.28 | E36: 微信付款 | F36: 外发加工费 | G36: 付AA喷砂厂喷砂委外加工 | H36: FP20250890 | I36: 已核销
A37: 2025-05-01 | B37: FK20250501418 | C37: BB抛光厂 | D37: 12090.05 | E37: G银行转账 | F37: 外发加工费 | G37: 付BB抛光厂抛光委外加工 | H37: FP20250291 | I37: 已核销
A38: 2025-05-18 | B38: FK20250518330 | C38: XX化工 | D38: 8507.65 | E38: G银行转账 | F38: 材料费 | G38: 付XX化工三酸/片碱/亚钠 | H38: FP20250929 | I38: 已核销
A39: 2025-05-27 | B39: FK20250527763 | C39: XX化工 | D39: 7190.99 | E39: G银行转账 | F39: 材料费 | G39: 付XX化工三酸/片碱/亚钠 | H39: FP20250927 | I39: 未核销
A40: (新增数据请在此行下方添加) | B40: =IF(A3="","",TEXT(A3,"FKyyyymmdd")&TEXT(ROW(),"000")) | F40: 其他 | H40: FP20250938 | I40: 未核销
...

Sheet 资金汇总
A1: 【本月资金收支汇总】
A2: 项目 | B2: G银行 | C2: N银行/微信 | D2: 现金 | E2: 合计
A3: 期初余额 | B3: 0 | C3: 0 | D3: 0 | E3: =SUM(B3:D3)
A4: 本月收入 | B4: =SUMIFS(收款记录!D:D,收款记录!E:E,"G银行转账",收款记录!A:A,">="&DATE(YEAR(TODAY()),MONTH(TODAY()),1),收款记录!A:A,"<"&DATE(YEAR(TODAY()),MONTH(TODAY())+1,1)) | C4: =SUMIFS(收款记录!D:D,收款记录!E:E,"N银行转账",收款记录!A:A,">="&DATE(YEAR(TODAY()),MONTH(TODAY()),1),收款记录!A:A,"<"&DATE(YEAR(TODAY()),MONTH(TODAY())+1,1))+SUMIFS(收款记录!D:D,收款记录!E:E,"微信收款",收款记录!A:A,">="&DATE(YEAR(TODAY()),MONTH(TODAY()),1),收款记录!A:A,"<"&DATE(YEAR(TODAY()),MONTH(TODAY())+1,1)) | D4: =SUMIFS(收款记录!D:D,收款记录!E:E,"现金",收款记录!A:A,">="&DATE(YEAR(TODAY()),MONTH(TODAY()),1),收款记录!A:A,"<"&DATE(YEAR(TODAY()),MONTH(TODAY())+1,1)) | E4: =SUM(B4:D4)
A5: 本月支出 | B5: =SUMIFS(付款记录!D:D,付款记录!E:E,"G银行转账",付款记录!A:A,">="&DATE(YEAR(TODAY()),MONTH(TODAY()),1),付款记录!A:A,"<"&DATE(YEAR(TODAY()),MONTH(TODAY())+1,1)) | C5: =SUMIFS(付款记录!D:D,付款记录!E:E,"N银行转账",付款记录!A:A,">="&DATE(YEAR(TODAY()),MONTH(TODAY()),1),付款记录!A:A,"<"&DATE(YEAR(TODAY()),MONTH(TODAY())+1,1))+SUMIFS(付款记录!D:D,付款记录!E:E,"微信付款",付款记录!A:A,">="&DATE(YEAR(TODAY()),MONTH(TODAY()),1),付款记录!A:A,"<"&DATE(YEAR(TODAY()),MONTH(TODAY())+1,1)) | D5: =SUMIFS(付款记录!D:D,付款记录!E:E,"现金",付款记录!A:A,">="&DATE(YEAR(TODAY()),MONTH(TODAY()),1),付款记录!A:A,"<"&DATE(YEAR(TODAY()),MONTH(TODAY())+1,1)) | E5: =SUM(B5:D5)
A6: 期末余额 | B6: =B3+B4-B5 | C6: =C3+C4-C5 | D6: =D3+D4-D5 | E6: =E3+E4-E5
A8: 【按费用分类汇总】
A9: 费用分类 | B9: 本月金额 | C9: 占比 | D9: 累计金额
A10: 材料费 | B10: =SUMIFS(付款记录!D:D,付款记录!F:F,A10,付款记录!A:A,">="&DATE(YEAR(TODAY()),MONTH(TODAY()),1),付款记录!A:A,"<"&DATE(YEAR(TODAY()),MONTH(TODAY())+1,1)) | C10: =IF($B$18=0,0,B10/$B$18) | D10: =SUMIFS(付款记录!D:D,付款记录!F:F,A10)
A11: 人工费 | B11: =SUMIFS(付款记录!D:D,付款记录!F:F,A11,付款记录!A:A,">="&DATE(YEAR(TODAY()),MONTH(TODAY()),1),付款记录!A:A,"<"&DATE(YEAR(TODAY()),MONTH(TODAY())+1,1)) | C11: =IF($B$18=0,0,B11/$B$18) | D11: =SUMIFS(付款记录!D:D,付款记录!F:F,A11)
A12: 房租 | B12: =SUMIFS(付款记录!D:D,付款记录!F:F,A12,付款记录!A:A,">="&DATE(YEAR(TODAY()),MONTH(TODAY()),1),付款记录!A:A,"<"&DATE(YEAR(TODAY()),MONTH(TODAY())+1,1)) | C12: =IF($B$18=0,0,B12/$B$18) | D12: =SUMIFS(付款记录!D:D,付款记录!F:F,A12)
A13: 水电费 | B13: =SUMIFS(付款记录!D:D,付款记录!F:F,A13,付款记录!A:A,">="&DATE(YEAR(TODAY()),MONTH(TODAY()),1),付款记录!A:A,"<"&DATE(YEAR(TODAY()),MONTH(TODAY())+1,1)) | C13: =IF($B$18=0,0,B13/$B$18) | D13: =SUMIFS(付款记录!D:D,付款记录!F:F,A13)
A14: 外发加工费 | B14: =SUMIFS(付款记录!D:D,付款记录!F:F,A14,付款记录!A:A,">="&DATE(YEAR(TODAY()),MONTH(TODAY()),1),付款记录!A:A,"<"&DATE(YEAR(TODAY()),MONTH(TODAY())+1,1)) | C14: =IF($B$18=0,0,B14/$B$18) | D14: =SUMIFS(付款记录!D:D,付款记录!F:F,A14)
A15: 日常费用 | B15: =SUMIFS(付款记录!D:D,付款记录!F:F,A15,付款记录!A:A,">="&DATE(YEAR(TODAY()),MONTH(TODAY()),1),付款记录!A:A,"<"&DATE(YEAR(TODAY()),MONTH(TODAY())+1,1)) | C15: =IF($B$18=0,0,B15/$B$18) | D15: =SUMIFS(付款记录!D:D,付款记录!F:F,A15)
A16: 税费 | B16: =SUMIFS(付款记录!D:D,付款记录!F:F,A16,付款记录!A:A,">="&DATE(YEAR(TODAY()),MONTH(TODAY()),1),付款记录!A:A,"<"&DATE(YEAR(TODAY()),MONTH(TODAY())+1,1)) | C16: =IF($B$18=0,0,B16/$B$18) | D16: =SUMIFS(付款记录!D:D,付款记录!F:F,A16)
A17: 其他 | B17: =SUMIFS(付款记录!D:D,付款记录!F:F,A17,付款记录!A:A,">="&DATE(YEAR(TODAY()),MONTH(TODAY()),1),付款记录!A:A,"<"&DATE(YEAR(TODAY()),MONTH(TODAY())+1,1)) | C17: =IF($B$18=0,0,B17/$B$18) | D17: =SUMIFS(付款记录!D:D,付款记录!F:F,A17)
A18: 合计 | B18: =SUM(B10:B17) | C18: 1 | D18: =SUM(D10:D17)
A20: 【按月份收付款趋势】
A21: 月份 | B21: 收款合计 | C21: 付款合计 | D21: 净流入
A22: 2025-03 | B22: =SUMPRODUCT((TEXT(收款记录!A:A,"yyyy-mm")=A22)*收款记录!D:D) | C22: =SUMPRODUCT((TEXT(付款记录!A:A,"yyyy-mm")=A22)*付款记录!D:D) | D22: =B22-C22
A23: 2025-04 | B23: =SUMPRODUCT((TEXT(收款记录!A:A,"yyyy-mm")=A23)*收款记录!D:D) | C23: =SUMPRODUCT((TEXT(付款记录!A:A,"yyyy-mm")=A23)*付款记录!D:D) | D23: =B23-C23
A24: 2025-05 | B24: =SUMPRODUCT((TEXT(收款记录!A:A,"yyyy-mm")=A24)*收款记录!D:D) | C24: =SUMPRODUCT((TEXT(付款记录!A:A,"yyyy-mm")=A24)*付款记录!D:D) | D24: =B24-C24
A25: 合计 | B25: =SUM(B22:B24) | C25: =SUM(C22:C24) | D25: =SUM(D22:D24)
A27: 说明：所有数据通过公式自动从"收款记录"和"付款记录"工作表汇总计算，无需手动填写。

Sheet G银行
A1: G银行流水（对公账户 - 有票）
A2: 日期 | B2: 单据号 | C2: 摘要 | D2: 收入(元) | E2: 支出(元) | F2: 余额(元)
A3: 2025-03-01 | C3: 期初余额 | D3: 0 | E3: 0 | F3: 85000
A4: 2025-03-19 | B4: SK20250319172 | C4: 收华泰金属加工费 | D4: 12591.92 | E4: 0 | F4: 97591.92
A5: 2025-03-23 | B5: SK20250323980 | C5: 收永达五金厂加工费 | D5: 6120.95 | E5: 0 | F5: 103712.87
A6: 2025-03-14 | B6: SK20250314789 | C6: 收瑞丰金属加工费 | D6: 17549.06 | E6: 0 | F6: 121261.93
A7: 2025-03-28 | B7: SK20250328649 | C7: 收恒丰铝业加工费 | D7: 6475.81 | E7: 0 | F7: 127737.74
A8: 2025-03-02 | B8: FK20250302871 | C8: 付BB抛光厂抛光委外加工 | D8: 0 | E8: 12622.4 | F8: 115115.34
A9: 2025-03-07 | B9: FK20250307488 | C9: 付AA喷砂厂喷砂委外加工 | D9: 0 | E9: 13585.42 | F9: 101529.92
A10: 2025-03-07 | B10: FK20250307693 | C10: 付ZZ挂具厂挂具 | D10: 0 | E10: 3656.66 | F10: 97873.26
A11: 2025-03-02 | B11: FK20250302170 | C11: 付BB抛光厂抛光委外加工 | D11: 0 | E11: 1661.62 | F11: 96211.64
A12: 2025-03-20 | B12: FK20250320513 | C12: 付XX化工三酸/片碱/亚钠 | D12: 0 | E12: 10290.58 | F12: 85921.06
A13: 2025-03-17 | B13: FK20250317785 | C13: 付ZZ挂具厂挂具 | D13: 0 | E13: 14053.24 | F13: 71867.82
A14: 2025-03-22 | B14: FK20250322109 | C14: 付ZZ挂具厂挂具 | D14: 0 | E14: 7129.76 | F14: 64738.06
A15: 2025-03-15 | C15: 付房租 | D15: 0 | E15: 8000 | F15: 56738.06
A16: 2025-04-01 | C16: 期初余额 | D16: 0 | E16: 0 | F16: 56738.06
A17: 2025-04-06 | B17: SK20250406960 | C17: 收瑞丰金属加工费 | D17: 10101.26 | E17: 0 | F17: 66839.32
A18: 2025-04-21 | B18: SK20250421830 | C18: 收华泰金属加工费 | D18: 6942.75 | E18: 0 | F18: 73782.07
A19: 2025-04-18 | B19: SK20250418952 | C19: 收瑞丰金属加工费 | D19: 9483.94 | E19: 0 | F19: 83266.01
A20: 2025-04-13 | B20: FK20250413185 | C20: 付BB抛光厂抛光委外加工 | D20: 0 | E20: 8683.68 | F20: 74582.33
A21: 2025-04-02 | B21: FK20250402565 | C21: 付ZZ挂具厂挂具 | D21: 0 | E21: 5997.01 | F21: 68585.32
A22: 2025-04-25 | B22: FK20250425581 | C22: 付AA喷砂厂喷砂委外加工 | D22: 0 | E22: 4157.94 | F22: 64427.38
A23: 2025-04-21 | B23: FK20250421872 | C23: 付XX化工三酸/片碱/亚钠 | D23: 0 | E23: 11827.88 | F23: 52599.5
A24: 2025-04-01 | B24: FK20250401736 | C24: 付YY化工色粉/除油剂 | D24: 0 | E24: 3390.73 | F24: 49208.77
A25: 2025-04-05 | B25: FK20250405677 | C25: 付YY化工色粉/除油剂 | D25: 0 | E25: 2330.2 | F25: 46878.57
A26: 2025-04-15 | C26: 付房租 | D26: 0 | E26: 8000 | F26: 38878.57
A27: 2025-05-01 | C27: 期初余额 | D27: 0 | E27: 0 | F27: 38878.57
A28: 2025-05-16 | B28: SK20250516542 | C28: 收瑞丰金属加工费 | D28: 3447.95 | E28: 0 | F28: 42326.52
A29: 2025-05-24 | B29: SK20250524193 | C29: 收天成铝材加工费 | D29: 12866.85 | E29: 0 | F29: 55193.37
A30: 2025-05-25 | B30: FK20250525773 | C30: 付AA喷砂厂喷砂委外加工 | D30: 0 | E30: 13041.2 | F30: 42152.17
A31: 2025-05-28 | B31: FK20250528292 | C31: 付BB抛光厂抛光委外加工 | D31: 0 | E31: 7198.66 | F31: 34953.51
A32: 2025-05-01 | B32: FK20250501418 | C32: 付BB抛光厂抛光委外加工 | D32: 0 | E32: 12090.05 | F32: 22863.46
A33: 2025-05-18 | B33: FK20250518330 | C33: 付XX化工三酸/片碱/亚钠 | D33: 0 | E33: 8507.65 | F33: 14355.81
A34: 2025-05-27 | B34: FK20250527763 | C34: 付XX化工三酸/片碱/亚钠 | D34: 0 | E34: 7190.99 | F34: 7164.82
A35: 2025-05-15 | C35: 付房租 | D35: 0 | E35: 8000 | F35: -835.18

Sheet N银行微信
A1: N银行/微信流水（当现金用）
A2: 日期 | B2: 单据号 | C2: 摘要 | D2: 收入(元) | E2: 支出(元) | F2: 余额(元)
A3: 2025-03-01 | C3: 期初余额 | D3: 0 | E3: 0 | F3: 5000
A4: 2025-03-27 | B4: SK20250327884 | C4: 收恒丰铝业加工费 | D4: 19603.72 | E4: 0 | F4: 24603.72
A5: 2025-03-05 | B5: SK20250305269 | C5: 收鑫达精密加工费 | D5: 13875.51 | E5: 0 | F5: 38479.23
A6: 2025-03-09 | B6: SK20250309873 | C6: 收宏盛五金加工费 | D6: 19358.53 | E6: 0 | F6: 57837.76
A7: 2025-03-24 | B7: SK20250324787 | C7: 收华泰金属加工费 | D7: 14833.08 | E7: 0 | F7: 72670.84
A8: 2025-03-21 | B8: SK20250321562 | C8: 收天成铝材加工费 | D8: 9885.8 | E8: 0 | F8: 82556.64
A9: 2025-03-04 | B9: SK20250304121 | C9: 收华泰金属加工费 | D9: 6044.55 | E9: 0 | F9: 88601.19
A10: 2025-03-11 | B10: SK20250311785 | C10: 收恒丰铝业加工费 | D10: 11254.81 | E10: 0 | F10: 99856
A11: 2025-03-16 | B11: SK20250316690 | C11: 收华泰金属加工费 | D11: 11706.21 | E11: 0 | F11: 111562.21
A12: 2025-03-16 | B12: SK20250316294 | C12: 收华泰金属加工费 | D12: 16123.15 | E12: 0 | F12: 127685.36
A13: 2025-03-04 | B13: SK20250304533 | C13: 收恒丰铝业加工费 | D13: 13861.69 | E13: 0 | F13: 141547.05
A14: 2025-03-21 | B14: SK20250321919 | C14: 收恒丰铝业加工费 | D14: 3091.03 | E14: 0 | F14: 144638.08
A15: 2025-03-05 | B15: FK20250305355 | C15: 付AA喷砂厂喷砂委外加工 | D15: 0 | E15: 3160.58 | F15: 141477.5
... A24: 2025-03-23 | B24: FK20250323234 | C24: 付ZZ挂具厂挂具 | D24: 0 | E24: 3960.95 | F24: 93790.88
A25: 2025-04-01 | C25: 期初余额 | D25: 0 | E25: 0 | F25: 93790.88
A26: 2025-04-22 | B26: SK20250422727 | C26: 收天成铝材加工费 | D26: 19100.71 | E26: 0 | F26: 112891.59
A27: 2025-04-27 | B27: SK20250427556 | C27: 收宏盛五金加工费 | D27: 16950.25 | E27: 0 | F27: 129841.84
A28: 2025-04-21 | B28: SK20250421596 | C28: 收博远五金加工费 | D28: 15784.65 | E28: 0 | F28: 145626.49
A29: 2025-04-10 | B29: SK20250410653 | C29: 收华泰金属加工费 | D29: 6890.87 | E29: 0 | F29: 152517.36
A30: 2025-04-03 | B30: SK20250403810 | C30: 收鑫达精密加工费 | D30: 4714.95 | E30: 0 | F30: 157232.31
A31: 2025-04-05 | B31: SK20250405438 | C31: 收华泰金属加工费 | D31: 3156.12 | E31: 0 | F31: 160388.43
A32: 2025-04-14 | B32: SK20250414812 | C32: 收宏盛五金加工费 | D32: 18287.09 | E32: 0 | F32: 178675.52
A33: 2025-04-01 | B33: SK20250401405 | C33: 收宏盛五金加工费 | D33: 10585.64 | E33: 0 | F33: 189261.16
A34: 2025-04-25 | B34: SK20250425651 | C34: 收宏盛五金加工费 | D34: 17362.06 | E34: 0 | F34: 206623.22
A35: 2025-04-24 | B35: SK20250424546 | C35: 收华泰金属加工费 | D35: 10788.13 | E35: 0 | F35: 217411.35
A36: 2025-04-16 | B36: SK20250416841 | C36: 收永达五金厂加工费 | D36: 8999.43 | E36: 0 | F36: 226410.78
A37: 2025-04-06 | B37: SK20250406646 | C37: 收瑞丰金属加工费 | D37: 18551.75 | E37: 0 | F37: 244962.53
... A41: 2025-04-07 | B41: FK20250407271 | C41: 付AA喷砂厂喷砂委外加工 | D41: 0 | E41: 10642.24 | F41: 219059.58
A42: 2025-05-01 | C42: 期初余额 | D42: 0 | E42: 0 | F42: 219059.58
A43: 2025-05-02 | B43: SK20250502866 | C43: 收鑫达精密加工费 | D43: 16267.31 | E43: 0 | F43: 235326.89
A44: 2025-05-27 | B44: SK20250527805 | C44: 收博远五金加工费 | D44: 9904.76 | E44: 0 | F44: 245231.65
A45: 2025-05-10 | B45: SK20250510652 | C45: 收宏盛五金加工费 | D45: 18968.17 | E45: 0 | F45: 264199.82
A46: 2025-05-08 | B46: SK20250508690 | C46: 收永达五金厂加工费 | D46: 19992.3 | E46: 0 | F46: 284192.12
A47: 2025-05-02 | B47: SK20250502384 | C47: 收鑫达精密加工费 | D47: 10469.01 | E47: 0 | F47: 294661.13
A48: 2025-05-06 | B48: SK20250506193 | C48: 收宏盛五金加工费 | D48: 13426.12 | E48: 0 | F48: 308087.25
A49: 2025-05-16 | B49: SK20250516786 | C49: 收天成铝材加工费 | D49: 9350.27 | E49: 0 | F49: 317437.52
A50: 2025-05-28 | B50: FK20250528395 | C50: 付YY化工色粉/除油剂 | D50: 0 | E50: 5282.15 | F50: 312155.37
A51: 2025-05-22 | B51: FK20250522137 | C51: 付AA喷砂厂喷砂委外加工 | D51: 0 | E51: 12296.71 | F51: 299858.66
...

Sheet 委外加工
A1: 委外加工记录（喷砂/拉丝/抛光委外）
A2: 日期 | B2: 单据号 | C2: 工序 | D2: 委外厂家 | E2: 数量 | F2: 单位 | G2: 单价(元) | H2: 金额(元) | I2: 状态
A3: 2025-03-20 | B3: WG20250320318 | C3: 拉丝 | D3: AA喷砂厂 | E3: 202 | F3: 件 | G3: 0.89 | H3: 179.36 | I3: 已完成
A4: 2025-03-17 | B4: WG20250317170 | C4: 抛光 | D4: BB抛光厂 | E4: 235 | F4: 件 | G4: 1.92 | H4: 451.18 | I4: 已完成
A5: 2025-03-08 | B5: WG20250308953 | C5: 抛光 | D5: BB抛光厂 | E5: 391 | F5: 件 | G5: 0.99 | H5: 386.81 | I5: 已完成
A6: 2025-03-18 | B6: WG20250318926 | C6: 拉丝 | D6: AA喷砂厂 | E6: 409 | F6: 件 | G6: 1.53 | H6: 627.41 | I6: 已完成
A7: 2025-03-21 | B7: WG20250321667 | C7: 拉丝 | D7: AA喷砂厂 | E7: 108 | F7: 件 | G7: 1.6 | H7: 172.96 | I7: 已完成
A8: 2025-03-10 | B8: WG20250310237 | C8: 拉丝 | D8: AA喷砂厂 | E8: 206 | F8: 件 | G8: 1.93 | H8: 396.9 | I8: 已完成
A9: 2025-04-25 | B9: WG20250425126 | C9: 喷砂 | D9: AA喷砂厂 | E9: 418 | F9: 件 | G9: 0.93 | H9: 388.62 | I9: 已完成
A10: 2025-04-10 | B10: WG20250410484 | C10: 拉丝 | D10: AA喷砂厂 | E10: 793 | F10: 件 | G10: 1.89 | H10: 1498.48 | I10: 已完成
A11: 2025-04-13 | B11: WG20250413807 | C11: 拉丝 | D11: AA喷砂厂 | E11: 303 | F11: 件 | G11: 0.89 | H11: 270.03 | I11: 已完成
A12: 2025-05-16 | B12: WG20250516379 | C12: 拉丝 | D12: AA喷砂厂 | E12: 398 | F12: 件 | G12: 1.41 | H12: 561.44 | I12: 已完成
A13: 2025-05-14 | B13: WG20250514664 | C13: 抛光 | D13: BB抛光厂 | E13: 583 | F13: 件 | G13: 1.09 | H13: 636.91 | I13: 已完成
A14: 2025-05-05 | B14: WG20250505620 | C14: 抛光 | D14: BB抛光厂 | E14: 295 | F14: 件 | G14: 1.91 | H14: 562.34 | I14: 已完成
A15: 2025-05-24 | B15: WG20250524891 | C15: 喷砂 | D15: AA喷砂厂 | E15: 984 | F15: 件 | G15: 0.88 | H15: 869.63 | I15: 已完成
A16: 合计 | H16: =SUM(H3:H15)

Sheet 材料库存
A1: 材料库存管理
A2: 材料名称 | B2: 规格 | C2: 单位 | D2: 期初库存 | E2: 本月入库 | F2: 本月出库 | G2: 期末库存 | H2: 安全库存 | I2: 库存预警
A3: 硫酸 | B3: 浓度98% | C3: kg | D3: 800 | E3: 635 | F3: 555 | G3: =D3+E3-F3 | H3: 500 | I3: =IF(G3<H3,"低库存!","正常")
A4: 硝酸 | B4: 浓度65% | C4: kg | D4: 500 | E4: 535 | F4: 639 | G4: =D4+E4-F4 | H4: 300 | I4: =IF(G4<H4,"低库存!","正常")
A5: 铬酸 | B5: 工业级 | C5: kg | D5: 350 | E5: 890 | F5: 583 | G5: =D5+E5-F5 | H5: 200 | I5: =IF(G5<H5,"低库存!","正常")
A6: 片碱 | B6: 片状99% | C6: kg | D6: 600 | E6: 841 | F6: 826 | G6: =D6+E6-F6 | H6: 300 | I6: =IF(G6<H6,"低库存!","正常")
A7: 亚硝酸钠 | B7: 工业级 | C7: kg | D7: 400 | E7: 547 | F7: 724 | G7: =D7+E7-F7 | H7: 200 | I7: =IF(G7<H7,"低库存!","正常")
A8: 黑色色粉 | B8: 氧化专用 | C8: kg | D8: 80 | E8: 104 | F8: 73 | G8: =D8+E8-F8 | H8: 50 | I8: =IF(G8<H8,"低库存!","正常")
A9: 银白色色粉 | B9: 氧化专用 | C9: kg | D9: 80 | E9: 78 | F9: 70 | G9: =D9+E9-F9 | H9: 50 | I9: =IF(G9<H9,"低库存!","正常")
A10: 香槟色色粉 | B10: 氧化专用 | C10: kg | D10: 80 | E10: 72 | F10: 47 | G10: =D10+E10-F10 | H10: 50 | I10: =IF(G10<H10,"低库存!","正常")
A11: 蓝色色粉 | B11: 氧化专用 | C11: kg | D11: 80 | E11: 86 | F11: 66 | G11: =D11+E11-F11 | H11: 50 | I11: =IF(G11<H11,"低库存!","正常")
A12: 除油剂 | B12: 工业级 | C12: L | D12: 150 | E12: 143 | F12: 106 | G12: =D12+E12-F12 | H12: 100 | I12: =IF(G12<H12,"低库存!","正常")
A13: 挂具 | B13: 铝合金 | C13: 套 | D13: 40 | E13: 30 | F13: 23 | G13: =D13+E13-F13 | H13: 20 | I13: =IF(G13<H13,"低库存!","正常")

Sheet 工资表
A1: 发放日期 | B1: 月份 | C1: 姓名 | D1: 部门 | E1: 岗位 | F1: 基本工资 | G1: 加班费 | H1: 应发合计 | I1: 社保公积金(个人) | J1: 个税 | K1: 实发工资
A2: 2025-03-10 | B2: 2025-03 | C2: 张三 | D2: 生产部 | E2: 操作工 | F2: 3800 | G2: 397 | H2: 4197 | I2: 399 | J2: 0 | K2: 3798
A3: 2025-03-10 | B3: 2025-03 | C3: 李四 | D3: 生产部 | E3: 操作工 | F3: 4000 | G3: 1335 | H3: 5335 | I3: 420 | J3: 0 | K3: 4915
A4: 2025-03-10 | B4: 2025-03 | C4: 王五 | D4: 生产部 | E4: 班长 | F4: 4500 | G4: 1114 | H4: 5614 | I4: 472.5 | J4: 4.25 | K4: 5137.25
A5: 2025-03-10 | B5: 2025-03 | C5: 赵六 | D5: 生产部 | E5: 操作工 | F5: 3800 | G5: 233 | H5: 4033 | I5: 399 | J5: 0 | K5: 3634
A6: 2025-03-10 | B6: 2025-03 | C6: 陈七 | D6: 管理部 | E6: 会计 | F6: 5000 | G6: 423 | H6: 5423 | I6: 525 | J6: 0 | K6: 4898
A7: 2025-03-10 | B7: 2025-03 | C7: 刘八 | D7: 管理部 | E7: 老板 | F7: 8000 | G7: 316 | H7: 8316 | I7: 840 | J7: 74.28 | K7: 7401.72
A8: 2025-04-10 | B8: 2025-04 | C8: 张三 | D8: 生产部 | E8: 操作工 | F8: 3800 | G8: 1246 | H8: 5046 | I8: 399 | J8: 0 | K8: 4647
A9: 2025-04-10 | B9: 2025-04 | C9: 李四 | D9: 生产部 | E9: 操作工 | F9: 4000 | G9: 364 | H9: 4364 | I9: 420 | J9: 0 | K9: 3944
A10: 2025-04-10 | B10: 2025-04 | C10: 王五 | D10: 生产部 | E10: 班长 | F10: 4500 | G10: 1046 | H10: 5546 | I10: 472.5 | J10: 2.21 | K10: 5071.29
A11: 2025-04-10 | B11: 2025-04 | C11: 赵六 | D11: 生产部 | E11: 操作工 | F11: 3800 | G11: 452 | H11: 4252 | I11: 399 | J11: 0 | K11: 3853
A12: 2025-04-10 | B12: 2025-04 | C12: 陈七 | D12: 管理部 | E12: 会计 | F12: 5000 | G12: 1026 | H12: 6026 | I12: 525 | J12: 15.03 | K12: 5485.97
A13: 2025-04-10 | B13: 2025-04 | C13: 刘八 | D13: 管理部 | E13: 老板 | F13: 8000 | G13: 1208 | H13: 9208 | I13: 840 | J13: 101.04 | K13: 8266.96
... A19: 2025-05-10 | B19: 2025-05 | C19: 刘八 | D19: 管理部 | E19: 老板 | F19: 8000 | G19: 424 | H19: 8424 | I19: 840 | J19: 77.52 | K19: 7506.48
A20: 2025-03 合计 | F20: =SUMPRODUCT((B$2:B$19="2025-03")*F$2:F$19) | G20: =SUMPRODUCT((B$2:B$19="2025-03")*G$2:G$19) | H20: =SUMPRODUCT((B$2:B$19="2025-03")*H$2:H$19) | I20: =SUMPRODUCT((B$2:B$19="2025-03")*I$2:I$19) | J20: =SUMPRODUCT((B$2:B$19="2025-03")*J$2:J$19) | K20: =SUMPRODUCT((B$2:B$19="2025-03")*K$2:K$19)
A21: 2025-04 合计 | F21: =SUMPRODUCT((B$2:B$20="2025-04")*F$2:F$20) | G21: =SUMPRODUCT((B$2:B$20="2025-04")*G$2:G$20) | H21: =SUMPRODUCT((B$2:B$20="2025-04")*H$2:H$20) | I21: =SUMPRODUCT((B$2:B$20="2025-04")*I$2:I$20) | J21: =SUMPRODUCT((B$2:B$20="2025-04")*J$2:J$20) | K21: =SUMPRODUCT((B$2:B$20="2025-04")*K$2:K$20)
A22: 2025-05 合计 | F22: =SUMPRODUCT((B$2:B$21="2025-05")*F$2:F$21) | G22: =SUMPRODUCT((B$2:B$21="2025-05")*G$2:G$21) | H22: =SUMPRODUCT((B$2:B$21="2025-05")*H$2:H$21) | I22: =SUMPRODUCT((B$2:B$21="2025-05")*I$2:I$21) | J22: =SUMPRODUCT((B$2:B$21="2025-05")*J$2:J$21) | K22: =SUMPRODUCT((B$2:B$21="2025-05")*K$2:K$21)

Sheet 费用明细
A1: 日期 | B1: 费用项目 | C1: 金额(元) | D1: 付款方式 | E1: 归属期间 | F1: 备注
A2: 2025-03-04 | B2: 除油剂 | C2: 215.24 | D2: G银行转账 | E2: 2025-03
A3: 2025-03-06 | B3: 三酸(硫酸/硝酸/铬酸) | C3: 3632.28 | D3: 微信付款 | E3: 2025-03
A4: 2025-03-08 | B4: 委外加工-抛光 | C4: 386.81 | D4: G银行转账 | E4: 2025-03 | F4: BB抛光厂
A5: 2025-03-10 | B5: 工资 | C5: 29783.97 | D5: G银行转账 | E5: 2025-03 | F5: 员工工资
A6: 2025-03-10 | B6: 委外加工-拉丝 | C6: 396.9 | D6: G银行转账 | E6: 2025-03 | F6: AA喷砂厂
A7: 2025-03-11 | B7: 水费 | C7: 471.44 | D7: G银行转账 | E7: 2025-03
A8: 2025-03-15 | B8: 片碱 | C8: 552.7 | D8: 微信付款 | E8: 2025-03
A9: 2025-03-15 | B9: 房租 | C9: 8000 | D9: G银行转账 | E9: 2025-03 | F9: 厂房租金
A10: 2025-03-17 | B10: 委外加工-抛光 | C10: 451.18 | D10: G银行转账 | E10: 2025-03 | F10: BB抛光厂
A11: 2025-03-18 | B11: 色粉 | C11: 1862.24 | D11: G银行转账 | E11: 2025-03
A12: 2025-03-18 | B12: 日常费用 | C12: 431.74 | D12: G银行转账 | E12: 2025-03
A13: 2025-03-18 | B13: 委外加工-拉丝 | C13: 627.41 | D13: G银行转账 | E13: 2025-03 | F13: AA喷砂厂
A14: 2025-03-20 | B14: 委外加工-拉丝 | C14: 179.36 | D14: G银行转账 | E14: 2025-03 | F14: AA喷砂厂
A15: 2025-03-21 | B15: 电费 | C15: 4062.49 | D15: N银行转账 | E15: 2025-03
A16: 2025-03-21 | B16: 委外加工-拉丝 | C16: 172.96 | D16: G银行转账 | E16: 2025-03 | F16: AA喷砂厂
A17: 2025-03-23 | B17: 亚硝酸钠 | C17: 300.45 | D17: N银行转账 | E17: 2025-03
A18: 2025-03-23 | B18: 挂具 | C18: 353.71 | D18: G银行转账 | E18: 2025-03
A19: 2025-03-27 | B19: 日常费用 | C19: 108.82 | D19: N银行转账 | E19: 2025-03
A20: 2025-04-10 | B20: 工资 | C20: 31268.22 | D20: G银行转账 | E20: 2025-04 | F20: 员工工资
A21: 2025-04-10 | B21: 委外加工-拉丝 | C21: 1498.48 | D21: G银行转账 | E21: 2025-04 | F21: AA喷砂厂
A22: 2025-04-13 | B22: 委外加工-拉丝 | C22: 270.03 | D22: G银行转账 | E22: 2025-04 | F22: AA喷砂厂
A23: 2025-04-14 | B23: 水费 | C23: 698.11 | D23: N银行转账 | E23: 2025-04
A24: 2025-04-14 | B24: 片碱 | C24: 566.37 | D24: G银行转账 | E24: 2025-04
A25: 2025-04-15 | B25: 日常费用 | C25: 268.02 | D25: N银行转账 | E25: 2025-04
A26: 2025-04-15 | B26: 房租 | C26: 8000 | D26: G银行转账 | E26: 2025-04 | F26: 厂房租金
A27: 2025-04-20 | B27: 除油剂 | C27: 394.26 | D27: 微信付款 | E27: 2025-04
A28: 2025-04-21 | B28: 电费 | C28: 3697.8 | D28: N银行转账 | E28: 2025-04
A29: 2025-04-21 | B29: 色粉 | C29: 603.44 | D29: N银行转账 | E29: 2025-04
A30: 2025-04-23 | B30: 三酸(硫酸/硝酸/铬酸) | C30: 1602.67 | D30: G银行转账 | E30: 2025-04
A31: 2025-04-24 | B31: 亚硝酸钠 | C31: 464.61 | D31: 微信付款 | E31: 2025-04
A32: 2025-04-25 | B32: 挂具 | C32: 105.06 | D32: N银行转账 | E32: 2025-04
A33: 2025-04-25 | B33: 委外加工-喷砂 | C33: 388.62 | D33: G银行转账 | E33: 2025-04 | F33: AA喷砂厂
A34: 2025-04-27 | B34: 日常费用 | C34: 198.04 | D34: 微信付款 | E34: 2025-04
A35: 2025-05-02 | B35: 亚硝酸钠 | C35: 259.44 | D35: N银行转账 | E35: 2025-05
A36: 2025-05-05 | B36: 日常费用 | C36: 191.07 | D36: N银行转账 | E36: 2025-05
A37: 2025-05-05 | B37: 委外加工-抛光 | C37: 562.34 | D37: G银行转账 | E37: 2025-05 | F37: BB抛光厂
A38: 2025-05-08 | B38: 片碱 | C38: 544.82 | D38: N银行转账 | E38: 2025-05
A39: 2025-05-10 | B39: 工资 | C39: 31557.95 | D39: G银行转账 | E39: 2025-05 | F39: 员工工资
A40: 2025-05-11 | B40: 水费 | C40: 449.28 | D40: G银行转账 | E40: 2025-05
...

Sheet 客户对账单
A1: 客户对账单汇总
A2: 对账期间：2025年3月 - 2025年5月
A3: 客户名称 | B3: 对账期间 | C3: 订单金额合计 | D3: 已收金额 | E3: 应收余额
A4: 永达五金厂 | B4: 2025-03 至 2025-05 | C4: =SUMIF(加工订单!C:C,A4,加工订单!K:K) | D4: =SUMIF(收款记录!C:C,A4,收款记录!D:D) | E4: =C4-D4
A5: 恒丰铝业 | B5: 2025-03 至 2025-05 | C5: =SUMIF(加工订单!C:C,A5,加工订单!K:K) | D5: =SUMIF(收款记录!C:C,A5,收款记录!D:D) | E5: =C5-D5
A6: 鑫达精密 | B6: 2025-03 至 2025-05 | C6: =SUMIF(加工订单!C:C,A6,加工订单!K:K) | D6: =SUMIF(收款记录!C:C,A6,收款记录!D:D) | E6: =C6-D6
A7: 华泰金属 | B7: 2025-03 至 2025-05 | C7: =SUMIF(加工订单!C:C,A7,加工订单!K:K) | D7: =SUMIF(收款记录!C:C,A7,收款记录!D:D) | E7: =C7-D7
A8: 博远五金 | B8: 2025-03 至 2025-05 | C8: =SUMIF(加工订单!C:C,A8,加工订单!K:K) | D8: =SUMIF(收款记录!C:C,A8,收款记录!D:D) | E8: =C8-D8
A9: 天成铝材 | B9: 2025-03 至 2025-05 | C9: =SUMIF(加工订单!C:C,A9,加工订单!K:K) | D9: =SUMIF(收款记录!C:C,A9,收款记录!D:D) | E9: =C9-D9
A10: 宏盛五金 | B10: 2025-03 至 2025-05 | C10: =SUMIF(加工订单!C:C,A10,加工订单!K:K) | D10: =SUMIF(收款记录!C:C,A10,收款记录!D:D) | E10: =C10-D10
A11: 瑞丰金属 | B11: 2025-03 至 2025-05 | C11: =SUMIF(加工订单!C:C,A11,加工订单!K:K) | D11: =SUMIF(收款记录!C:C,A11,收款记录!D:D) | E11: =C11-D11
A12: 合计 | C12: =SUM(C4:C11) | D12: =SUM(D4:D11) | E12: =SUM(E4:E11)

Sheet 供应商对账单
A1: 供应商对账单汇总
A2: 对账期间：2025年3月 - 2025年5月
A3: 供应商名称 | B3: 采购金额合计 | C3: 已付金额 | D3: 应付余额 | E3: 账龄(天) | F3: 状态
A4: XX化工 | B4: =SUMIF(付款记录!C:C,A4,付款记录!D:D) | C4: =B4 | D4: =B4-C4 | E4: 30 | F4: 正常
A5: YY化工 | B5: =SUMIF(付款记录!C:C,A5,付款记录!D:D) | C5: =B5 | D5: =B5-C5 | E5: 30 | F5: 正常
A6: ZZ挂具厂 | B6: =SUMIF(付款记录!C:C,A6,付款记录!D:D) | C6: =B6 | D6: =B6-C6 | E6: 30 | F6: 正常
A7: AA喷砂厂 | B7: =SUMIF(付款记录!C:C,A7,付款记录!D:D) | C7: =B7 | D7: =B7-C7 | E7: 30 | F7: 正常
A8: BB抛光厂 | B8: =SUMIF(付款记录!C:C,A8,付款记录!D:D) | C8: =B8 | D8: =B8-C8 | E8: 30 | F8: 正常
A9: 合计 | B9: =SUM(B4:B8) | C9: =SUM(C4:C8) | D9: =SUM(D4:D8)

Sheet 税务管理
A1: 税务管理
A3: 【增值税（一般纳税人13%）】
A4: 项目 | B4: 金额(元)
A5: 销项税额（加工费收入x13%） | B5: =SUMIF(加工订单!L:L,">0",加工订单!J:J)
A6: 进项税额（材料采购等） | B6: 5000
A7: 应纳增值税额 | B7: =B5-B6
A9: 附加税费
A10: 城市维护建设税（7%） | B10: =B7*0.07
A11: 教育费附加（3%） | B11: =B7*0.03
A12: 地方教育附加（2%） | B12: =B7*0.02
A13: 附加税合计 | B13: =SUM(B10:B12)
A15: 【企业所得税（小型微利企业5%）】
A16: 项目 | B16: 金额(元)
A17: 营业收入 | B17: =SUM(加工订单!I:I)
A18: 营业成本（费用合计） | B18: =SUM(费用明细!C:C)
A19: 利润总额 | B19: =B17-B18
A20: 应纳税所得额 | B20: =B19
A21: 适用税率 | B21: 0.05
A22: 应纳所得税额 | B22: =B20*B21

Sheet 发票管理
A1: 发票管理
A3: 【销项发票】
A4: 日期 | B4: 发票号 | C4: 客户名称 | D4: 金额(不含税) | E4: 税率 | F4: 税额 | G4: 价税合计 | H4: 状态
A5: 2025-03-05 | B5: XS001001 | C5: 天成铝材 | D5: 22133.41 | E5: 0.13 | F5: 2877.34 | G5: 25010.75 | H5: 待开
A6: 2025-03-04 | B6: XS001002 | C6: 瑞丰金属 | D6: 3337.65 | E6: 0.13 | F6: 433.89 | G6: 3771.54 | H6: 已开具
A7: 2025-03-14 | B7: XS001003 | C7: 鑫达精密 | D7: 4646.22 | E7: 0.13 | F7: 604.01 | G7: 5250.23 | H7: 已开具
A8: 2025-03-11 | B8: XS001004 | C8: 宏盛五金 | D8: 17296.41 | E8: 0.13 | F8: 2248.53 | G8: 19544.94 | H8: 已开具
A9: 2025-04-28 | B9: XS001005 | C9: 宏盛五金 | D9: 23991.07 | E9: 0.13 | F9: 3118.84 | G9: 27109.91 | H9: 待开
A10: 2025-04-28 | B10: XS001006 | C10: 永达五金厂 | D10: 16584.11 | E10: 0.13 | F10: 2155.93 | G10: 18740.04 | H10: 已开具
A11: 2025-04-21 | B11: XS001007 | C11: 博远五金 | D11: 24943.37 | E11: 0.13 | F11: 3242.64 | G11: 28186.01 | H11: 已开具
A12: 2025-04-14 | B12: XS001008 | C12: 恒丰铝业 | D12: 19728.13 | E12: 0.13 | F12: 2564.66 | G12: 22292.79 | H12: 已开具
A13: 2025-04-15 | B13: XS001009 | C13: 鑫达精密 | D13: 18268.03 | E13: 0.13 | F13: 2374.84 | G13: 20642.87 | H13: 已开具
A14: 2025-04-02 | B14: XS001010 | C14: 天成铝材 | D14: 20515.16 | E14: 0.13 | F14: 2666.97 | G14: 23182.13 | H14: 已开具
A15: 2025-05-12 | B15: XS001011 | C15: 宏盛五金 | D15: 6202.54 | E15: 0.13 | F15: 806.33 | G15: 7008.87 | H15: 待开
A16: 2025-05-22 | B16: XS001012 | C16: 鑫达精密 | D16: 6739.64 | E16: 0.13 | F16: 876.15 | G16: 7615.79 | H16: 待开
... A19: 2025-05-09 | B19: XS001015 | C19: 永达五金厂 | D19: 22775.99 | E19: 0.13 | F19: 2960.88 | G19: 25736.87 | H19: 待开
A20: 合计 | D20: =SUM(D5:D19) | F20: =SUM(F5:F19) | G20: =SUM(G5:G19)
A22: 【进项发票】
A23: 日期 | B23: 发票号 | C23: 供应商名称 | D23: 金额(不含税) | E23: 税率 | F23: 税额 | G23: 价税合计 | H23: 状态
A24: 2025-03-18 | B24: JX002001 | C24: YY化工 | D24: 2034.07 | E24: 0.13 | F24: 264.43 | G24: 2298.5 | H24: 已收票
A25: 2025-03-19 | B25: JX002002 | C25: ZZ挂具厂 | D25: 9945.14 | E25: 0.13 | F25: 1292.87 | G25: 11238.01 | H25: 已收票
A26: 2025-03-23 | B26: JX002003 | C26: ZZ挂具厂 | D26: 7395.7 | E26: 0.13 | F26: 961.44 | G26: 8357.14 | H26: 已收票
A27: 2025-03-07 | B27: JX002004 | C27: AA喷砂厂 | D27: 12946.7 | E27: 0.13 | F27: 1683.07 | G27: 14629.77 | H27: 已收票
A28: 2025-04-13 | B28: JX002005 | C28: BB抛光厂 | D28: 6025.43 | E28: 0.13 | F28: 783.31 | G28: 6808.74 | H28: 已收票
A29: 2025-04-23 | B29: JX002006 | C29: ZZ挂具厂 | D29: 1307.15 | E29: 0.13 | F29: 169.93 | G29: 1477.08 | H29: 待收
A30: 2025-05-09 | B30: JX002007 | C30: XX化工 | D30: 8923.01 | E30: 0.13 | F30: 1159.99 | G30: 10083 | H30: 待收
A31: 2025-05-02 | B31: JX002008 | C31: BB抛光厂 | D31: 11432.41 | E31: 0.13 | F31: 1486.21 | G31: 12918.62 | H31: 已收票
A32: 2025-05-20 | B32: JX002009 | C32: ZZ挂具厂 | D32: 4066.06 | E32: 0.13 | F32: 528.59 | G32: 4594.65 | H32: 待收
A33: 合计 | D33: =SUM(D24:D32) | F33: =SUM(F24:F32) | G33: =SUM(G24:G32)

Sheet 利润表
A1: 利润表
A2: 会小企02表 编制单位：XX氧化加工厂 2025年5月 单位：元
A3: 项目 | B3: 行次 | C3: 本期金额 | D3: 本年累计
A4: 一、营业收入（加工费收入） | B4: 1 | C4: =SUMIF(加工订单!A:A,"2025-05*",加工订单!I:I) | D4: =SUM(加工订单!I:I)
A5: 减：营业成本 | B5: 2 | C5: =SUMIF(费用明细!E:E,"2025-05",费用明细!C:C) | D5: =SUM(费用明细!C:C)
A6: 营业税金及附加 | B6: 3 | C6: =税务管理!B12 | D6: =税务管理!B12
A7: 销售费用 | B7: 10 | C7: 0 | D7: 0
A8: 管理费用 | B8: 13 | C8: 0 | D8: 0
A9: 财务费用 | B9: 17 | C9: 0 | D9: 0
A10: 二、营业利润 | B10: 20 | C10: =C4-C5-C6-C7-C8-C9 | D10: =D4-D5-D6-D7-D8-D9
A11: 加：营业外收入 | B11: 21 | C11: 0 | D11: 0
A12: 减：营业外支出 | B12: 23 | C12: 0 | D12: 0
A13: 三、利润总额 | B13: 29 | C13: =C11+C12-C13 | D13: =D11+D12-D13
A14: 减：所得税费用 | B14: 30 | C14: =税务管理!B22 | D14: =税务管理!B22
A15: 四、净利润 | B15: 31 | C15: =C15-C16 | D15: =D15-D16

Sheet 资产负债表
A1: 资产负债表
A2: 会小企01表 编制单位：XX氧化加工厂 2025年5月31日 单位：元
A3: 资产 | B3: 行次 | C3: 期末余额 | D3: 负债和所有者权益 | E3: 期末余额
A4: 流动资产： | D4: 流动负债：
A5: 货币资金（G银行+N银行/微信） | B5: 1 | C5: 267710.92 | D5: 应付账款 | E5: 0
A6: 应收账款 | B6: 4 | C6: 0 | D6: 应付职工薪酬 | E6: 0
A7: 存货（材料） | B7: 9 | C7: 5000 | D7: 应交税费 | E7: 0
A8: 其他应收款 | B8: 8 | C8: 0 | D8: 其他应付款 | E8: 0
A9: 流动资产合计 | B9: 15 | C9: =C5+C6+C7+C8 | D9: 流动负债合计 | E9: =SUM(F5:F9)
A11: 非流动资产： | D11: 非流动负债：
A12: 固定资产 | B12: 18 | C12: 50000 | D12: 长期借款 | E12: 0
A13: 减：累计折旧 | B13: 19 | C13: 5000 | D13: 非流动负债合计 | E13: 0
A14: 固定资产账面价值 | B14: 20 | C14: =C12-C13 | D14: 负债合计 | E14: =F10+F15
A15: 非流动资产合计 | B15: 29 | C15: =C14
D16: 所有者权益：
D17: 实收资本 | E17: 100000
D18: 未分配利润 | E18: =C6+C9-C10-F16
D19: 所有者权益合计 | E19: =F18+F19
A21: 资产总计 | B21: 30 | C21: =C9+C15 | D21: 负债和所有者权益总计 | E21: =F16+F20

Sheet 图表分析
A1: 经营分析图表
A3: 【月度经营数据】
A4: 月份 | B4: 营业收入 | C4: 营业成本 | D4: 净利润
A5: 2025-03 | B5: 134544.68 | C5: 51989.7 | D5: 82554.98
A6: 2025-04 | B6: 51354.28 | C6: 50023.73 | D6: 1330.55
A7: 2025-05 | B7: 139969.65 | C7: 53640.5 | D7: 86329.15
A9: 【客户排名（按收入）】
A10: 客户名称 | B10: 累计金额(元)
A11: 华泰金属 | B11: 130632.72
A12: 瑞丰金属 | B12: 60407.22
A13: 博远五金 | B13: 52604.39
A14: 永达五金厂 | B14: 27425.65
A15: 宏盛五金 | B15: 26157.78
A16: 恒丰铝业 | B16: 15983.93
A17: 天成铝材 | B17: 7759.73
A18: 鑫达精密 | B18: 4897.19
A20: 【成本结构分析】
A21: 费用项目 | B21: 金额(元)
A22: 工资 | B22: 92610.14
A23: 房租 | B23: 24000
A24: 化工材料 | B24: 16362.23
A25: 水电费 | B25: 13139.93
A26: 委外加工费 | B26: 7002.07
A27: 日常费用 | B27: 1515.06
A28: 亚硝酸钠 | B28: 1024.5
A30: 【产品利润分析】
A31: 产品名称 | B31: 订单数 | C31: 总数量 | D31: 总金额(不含税) | E31: 平均单价 | F31: 占比
A32: 铝板氧化 | B32: 6 | C32: 7147 | D32: 172832.91 | E32: 24.18 | F32: 0.53037606
A33: 铝件氧化-香槟 | B33: 4 | C33: 5096 | D33: 23519.67 | E33: 4.62 | F33: 0.072175316
A34: 铝件氧化-银白 | B34: 5 | C34: 5204 | D34: 17558.67 | E34: 3.37 | F34: 0.053882668
A35: 铝件氧化-黑色 | B35: 5 | C35: 4227 | D35: 16549.04 | E35: 3.92 | F35: 0.050784394
A36: 铜件氧化 | B36: 9 | C36: 10862 | D36: 16291.5 | E36: 1.5 | F36: 0.049994076
A37: 铝管氧化 | B37: 7 | C37: 7705 | D37: 14198.23 | E37: 1.84 | F37: 0.043570413
A38: 铝件氧化-蓝色 | B38: 2 | C38: 2812 | D38: 13623.53 | E38: 4.84 | F38: 0.041806819
A39: 铝件喷砂+氧化 | B39: 5 | C39: 4693 | D39: 9252.59 | E39: 1.97 | F39: 0.028393622
A40: 铝件喷砂(委外) | B40: 4 | C40: 5349 | D40: 7936.48 | E40: 1.48 | F40: 0.024354847
A41: 铝件抛光+氧化 | B41: 2 | C41: 2188 | D41: 6631.09 | E41: 3.03 | F41: 0.020348968

Sheet 月度汇总
A1: 月度经营汇总
A2: 月份 | B2: 订单数 | C2: 营业收入(不含税) | D2: 税额 | E2: 价税合计 | F2: 费用合计 | G2: 利润
A3: 2025-03 | B3: =SUMPRODUCT((LEFT(加工订单!A:A,7)="2025-03")*1) | C3: =SUMPRODUCT((LEFT(加工订单!A:A,7)="2025-03")*加工订单!I:I) | D3: =SUMPRODUCT((LEFT(加工订单!A:A,7)="2025-03")*加工订单!J:J) | E3: =SUMPRODUCT((LEFT(加工订单!A:A,7)="2025-03")*加工订单!K:K) | F3: =SUMPRODUCT((费用明细!E:E="2025-03")*费用明细!C:C) | G3: =C3-F3
A4: 2025-04 | B4: =SUMPRODUCT((LEFT(加工订单!A:A,7)="2025-04")*1) | C4: =SUMPRODUCT((LEFT(加工订单!A:A,7)="2025-04")*加工订单!I:I) | D4: =SUMPRODUCT((LEFT(加工订单!A:A,7)="2025-04")*加工订单!J:J) | E4: =SUMPRODUCT((LEFT(加工订单!A:A,7)="2025-04")*加工订单!K:K) | F4: =SUMPRODUCT((费用明细!E:E="2025-04")*费用明细!C:C) | G4: =C4-F4
A5: 2025-05 | B5: =SUMPRODUCT((LEFT(加工订单!A:A,7)="2025-05")*1) | C5: =SUMPRODUCT((LEFT(加工订单!A:A,7)="2025-05")*加工订单!I:I) | D5: =SUMPRODUCT((LEFT(加工订单!A:A,7)="2025-05")*加工订单!J:J) | E5: =SUMPRODUCT((LEFT(加工订单!A:A,7)="2025-05")*加工订单!K:K) | F5: =SUMPRODUCT((费用明细!E:E="2025-05")*费用明细!C:C) | G5: =C5-F5
A6: 合计 | B6: =SUM(B3:B5) | C6: =SUM(C3:C5) | D6: =SUM(D3:D5) | E6: =SUM(E3:E5) | F6: =SUM(F3:F5) | G6: =SUM(G3:G5)

Sheet 年度对比分析
A1: 年度对比分析
A2: 各月经营数据对比与环比分析
A3: 月份 | B3: 订单数 | C3: 营业收入 | D3: 费用合计 | E3: 净利润 | F3: 毛利率 | G3: 收入环比 | H3: 利润环比
A4: 2025-03 | B4: =SUMPRODUCT((LEFT(加工订单!A:A,7)="2025-03")*1) | C4: =SUMPRODUCT((LEFT(加工订单!A:A,7)="2025-03")*加工订单!I:I) | D4: =SUMPRODUCT((费用明细!E:E="2025-03")*费用明细!C:C) | E4: =C4-D4 | F4: =IF(C4>0,(C4-D4)/C4,0) | G4: - | H4: -
A5: 2025-04 | B5: =SUMPRODUCT((LEFT(加工订单!A:A,7)="2025-04")*1) | C5: =SUMPRODUCT((LEFT(加工订单!A:A,7)="2025-04")*加工订单!I:I) | D5: =SUMPRODUCT((费用明细!E:E="2025-04")*费用明细!C:C) | E5: =C5-D5 | F5: =IF(C5>0,(C5-D5)/C5,0) | G5: =IF(C4>0,(C5-C4)/C4,0) | H5: =IF(E4>0,(E5-E4)/E4,0)
A6: 2025-05 | B6: =SUMPRODUCT((LEFT(加工订单!A:A,7)="2025-05")*1) | C6: =SUMPRODUCT((LEFT(加工订单!A:A,7)="2025-05")*加工订单!I:I) | D6: =SUMPRODUCT((费用明细!E:E="2025-05")*费用明细!C:C) | E6: =C6-D6 | F6: =IF(C6>0,(C6-D6)/C6,0) | G6: =IF(C5>0,(C6-C5)/C5,0) | H6: =IF(E5>0,(E6-E5)/E5,0)
A7: 累计合计 | B7: =SUM(B4:B6) | C7: =SUM(C4:C6) | D7: =SUM(D4:D6) | E7: =SUM(E4:E6) | F7: =IF(C7>0,(C7-D7)/C7,0)

Sheet 数据校验
A1: 数据一致性校验
A2: 校验时间：2025年5月31日
A3: 校验内容 | B3: 预期值 | C3: 实际值 | D3: 状态
A4: G银行期末余额 | B4: =G银行!F35 | C4: =G银行!F35 | D4: =IF(ABS(B4-C4)<0.01,"通过","异常")
A5: N银行期末余额 | B5: =N银行微信!F55 | C5: =N银行微信!F55 | D5: =IF(ABS(B5-C5)<0.01,"通过","异常")
A6: 收款合计 | B6: =收款记录!D41 | C6: =SUM(收款记录!D2:D40) | D6: =IF(ABS(B6-C6)<0.01,"通过","异常")
A7: 付款合计 | B7: =付款记录!D40 | C7: =SUM(付款记录!D2:D39) | D7: =IF(ABS(B7-C7)<0.01,"通过","异常")
A8: 订单金额合计 | B8: =SUM(加工订单!K:K) | C8: =SUM(加工订单!K:K) | D8: =IF(ABS(B8-C8)<0.01,"通过","异常")
A9: 应收余额合计 | B9: =SUM(应收应付!D3:D10) | C9: =SUM(应收应付!D3:D10) | D9: =IF(ABS(B9-C9)<0.01,"通过","异常")
A10: 应付余额合计 | B10: =SUMPRODUCT((应收应付!D14:D18)) | C10: =SUMPRODUCT((应收应付!D14:D18)) | D10: =IF(ABS(B10-C10)<0.01,"通过","异常")
A11: 利润表平衡 | B11: =利润表!C16 | C11: =利润表!C4-利润表!C5-利润表!C6-利润表!C7-利润表!C8-利润表!C9-利润表!C16 | D11: =IF(ABS(B11-C11)<0.01,"通过","异常")

Sheet 打印模板
A1: 永达五金厂 对账单
A2: 对账期间：2025年3月 - 2025年5月
A3: 打印日期：2025年5月31日
A5: 序号 | B5: 日期 | C5: 订单号 | D5: 产品名称 | E5: 金额(不含税) | F5: 价税合计
A6: 1 | B6: 2025-03-04 | C6: DD20250304001 | D6: 铝板氧化 | E6: 12248.38 | F6: 13840.67
A7: 2 | B7: 2025-03-17 | C7: DD20250317003 | D7: 铝件抛光+氧化 | E7: 4512.67 | F7: 5099.32
A8: 3 | B8: 2025-03-09 | C8: DD20250309007 | D8: 铝件喷砂(委外) | E8: 1799.56 | F8: 2033.5
A9: 4 | B9: 2025-03-08 | C9: DD20250308025 | D9: 铜件氧化 | E9: 2879.26 | F9: 3253.56
A10: 5 | B10: 2025-04-13 | C10: DD20250413006 | D10: 铝件抛光(委外) | E10: 1029.29 | F10: 1163.1
A11: 6 | B11: 2025-04-15 | C11: DD20250415024 | D11: 铜件氧化 | E11: 2549.6 | F11: 2881.05
A12: 7 | B12: 2025-05-28 | C12: DD20250528014 | D12: 铝管氧化 | E12: 1716.32 | F12: 1939.44
A13: 8 | B13: 2025-05-03 | C13: DD20250503016 | D13: 铝件喷砂+氧化 | E13: 690.57 | F13: 780.34
D14: 合计 | E14: =SUM(E6:E13) | F14: =SUM(F6:F13)
D15: 已收金额 | E15: =SUMIF(收款记录!C:C,"永达五金厂",收款记录!D:D)
D16: 应收余额 | E16: =F14-E15
A18: 供方（盖章）：__________________ | D18: 需方（盖章）：__________________
A22: 利润表
A23: 会小企02表 编制单位：XX氧化加工厂 2025年5月 单位：元
A24: 项目 | B24: 行次 | C24: 本期金额 | D24: 本年累计
A25: 一、营业收入（加工费收入） | B25: 1 | C25: =利润表!C4 | D25: =利润表!D4
A26: 减：营业成本 | B26: 2 | C26: =利润表!C5 | D26: =利润表!D5
A27: 营业税金及附加 | B27: 3 | C27: =利润表!C6 | D27: =利润表!D6
A28: 销售费用 | B28: 10 | C28: =利润表!C7 | D28: =利润表!D7
A29: 管理费用 | B29: 13 | C29: =利润表!C8 | D29: =利润表!D8
A30: 财务费用 | B30: 17 | C30: =利润表!C9 | D30: =利润表!D9
A31: 二、营业利润 | B31: 20 | C31: =利润表!C10 | D31: =利润表!D10
A32: 加：营业外收入 | B32: 21 | C32: =利润表!C11 | D32: =利润表!D11
A33: 减：营业外支出 | B33: 23 | C33: =利润表!C12 | D33: =利润表!D12
A34: 三、利润总额 | B34: 29 | C34: =利润表!C13 | D34: =利润表!D13
A35: 减：所得税费用 | B35: 30 | C35: =利润表!C14 | D35: =利润表!D14
A36: 四、净利润 | B36: 31 | C36: =利润表!C15 | D36: =利润表!D15
A38: 编制人：__________ 复核人：__________ 财务负责人：__________
A42: 工资表
A43: 2025年5月 单位：元
A44: 发放日期 | B44: 月份 | C44: 姓名 | D44: 部门 | E44: 岗位 | F44: 基本工资 | G44: 加班费 | H44: 应发合计 | I44: 社保公积金(个人) | J44: 个税 | K44: 实发工资
A45: 2025-05-10 | B45: 2025-05 | C45: 张三 | D45: 生产部 | E45: 操作工 | F45: 3800 | G45: 1185 | H45: 4985 | I45: 399 | J45: 0 | K45: 4586
A46: 2025-05-10 | B46: 2025-05 | C46: 李四 | D46: 生产部 | E46: 操作工 | F46: 4000 | G46: 622 | H46: 4622 | I46: 420 | J46: 0 | K46: 4202
A47: 2025-05-10 | B47: 2025-05 | C47: 王五 | D47: 生产部 | E47: 班长 | F47: 4500 | G47: 1401 | H47: 5901 | I47: 472.5 | J47: 12.85 | K47: 5415.65
A48: 2025-05-10 | B48: 2025-05 | C48: 赵六 | D48: 生产部 | E48: 操作工 | F48: 3800 | G48: 762 | H48: 4562 | I48: 399 | J48: 0 | K48: 4163
A49: 2025-05-10 | B49: 2025-05 | C49: 陈七 | D49: 管理部 | E49: 会计 | F49: 5000 | G49: 1231 | H49: 6231 | I49: 525 | J49: 21.18 | K49: 5684.82
...

Sheet 应收应付
A1: 【应收账款汇总 - 客户欠我方】
A2: 客户名称 | B2: 期初余额 | C2: 本月新增应收 | D2: 本月收回 | E2: 期末余额 | F2: 最后交易日期 | G2: 账龄(天) | H2: 状态
A3: 永达五金厂 | B3: 0 | C3: =SUMIFS(加工订单!K:K,加工订单!C:C,A3,加工订单!A:A,">="&DATE(YEAR(TODAY()),MONTH(TODAY()),1)) | D3: =SUMIFS(收款记录!D:D,收款记录!C:C,A3,收款记录!A:A,">="&DATE(YEAR(TODAY()),MONTH(TODAY()),1)) | E3: =B3+C3-D3 | F3: =MAX(IF(加工订单!C:C=A3,加工订单!A:A),IF(收款记录!C:C=A3,收款记录!A:A)) | G3: =IF(F3=0,0,TODAY()-F3) | H3: =IF(G3>90,"严重逾期",IF(G3>60,"逾期",IF(G3>30,"即将到期","正常")))
A4: 恒丰铝业 | B4: 0 | C4: =SUMIFS(加工订单!K:K,加工订单!C:C,A4,加工订单!A:A,">="&DATE(YEAR(TODAY()),MONTH(TODAY()),1)) | D4: =SUMIFS(收款记录!D:D,收款记录!C:C,A4,收款记录!A:A,">="&DATE(YEAR(TODAY()),MONTH(TODAY()),1)) | E4: =B4+C4-D4 | F4: =MAX(IF(加工订单!C:C=A4,加工订单!A:A),IF(收款记录!C:C=A4,收款记录!A:A)) | G4: =IF(F4=0,0,TODAY()-F4) | H4: =IF(G4>90,"严重逾期",IF(G4>60,"逾期",IF(G4>30,"即将到期","正常")))
A5: 鑫达精密 | B5: 0 | C5: =SUMIFS(加工订单!K:K,加工订单!C:C,A5,加工订单!A:A,">="&DATE(YEAR(TODAY()),MONTH(TODAY()),1)) | D5: =SUMIFS(收款记录!D:D,收款记录!C:C,A5,收款记录!A:A,">="&DATE(YEAR(TODAY()),MONTH(TODAY()),1)) | E5: =B5+C5-D5 | F5: =MAX(IF(加工订单!C:C=A5,加工订单!A:A),IF(收款记录!C:C=A5,收款记录!A:A)) | G5: =IF(F5=0,0,TODAY()-F5) | H5: =IF(G5>90,"严重逾期",IF(G5>60,"逾期",IF(G5>30,"即将到期","正常")))
A6: 华泰金属 | B6: 0 | C6: =SUMIFS(加工订单!K:K,加工订单!C:C,A6,加工订单!A:A,">="&DATE(YEAR(TODAY()),MONTH(TODAY()),1)) | D6: =SUMIFS(收款记录!D:D,收款记录!C:C,A6,收款记录!A:A,">="&DATE(YEAR(TODAY()),MONTH(TODAY()),1)) | E6: =B6+C6-D6 | F6: =MAX(IF(加工订单!C:C=A6,加工订单!A:A),IF(收款记录!C:C=A6,收款记录!A:A)) | G6: =IF(F6=0,0,TODAY()-F6) | H6: =IF(G6>90,"严重逾期",IF(G6>60,"逾期",IF(G6>30,"即将到期","正常")))
A7: 博远五金 | B7: 0 | C7: =SUMIFS(加工订单!K:K,加工订单!C:C,A7,加工订单!A:A,">="&DATE(YEAR(TODAY()),MONTH(TODAY()),1)) | D7: =SUMIFS(收款记录!D:D,收款记录!C:C,A7,收款记录!A:A,">="&DATE(YEAR(TODAY()),MONTH(TODAY()),1)) | E7: =B7+C7-D7 | F7: =MAX(IF(加工订单!C:C=A7,加工订单!A:A),IF(收款记录!C:C=A7,收款记录!A:A)) | G7: =IF(F7=0,0,TODAY()-F7) | H7: =IF(G7>90,"严重逾期",IF(G7>60,"逾期",IF(G7>30,"即将到期","正常")))
A8: 天成铝材 | B8: 0 | C8: =SUMIFS(加工订单!K:K,加工订单!C:C,A8,加工订单!A:A,">="&DATE(YEAR(TODAY()),MONTH(TODAY()),1)) | D8: =SUMIFS(收款记录!D:D,收款记录!C:C,A8,收款记录!A:A,">="&DATE(YEAR(TODAY()),MONTH(TODAY()),1)) | E8: =B8+C8-D8 | F8: =MAX(IF(加工订单!C:C=A8,加工订单!A:A),IF(收款记录!C:C=A8,收款记录!A:A)) | G8: =IF(F8=0,0,TODAY()-F8) | H8: =IF(G8>90,"严重逾期",IF(G8>60,"逾期",IF(G8>30,"即将到期","正常")))
A9: 宏盛五金 | B9: 0 | C9: =SUMIFS(加工订单!K:K,加工订单!C:C,A9,加工订单!A:A,">="&DATE(YEAR(TODAY()),MONTH(TODAY()),1)) | D9: =SUMIFS(收款记录!D:D,收款记录!C:C,A9,收款记录!A:A,">="&DATE(YEAR(TODAY()),MONTH(TODAY()),1)) | E9: =B9+C9-D9 | F9: =MAX(IF(加工订单!C:C=A9,加工订单!A:A),IF(收款记录!C:C=A9,收款记录!A:A)) | G9: =IF(F9=0,0,TODAY()-F9) | H9: =IF(G9>90,"严重逾期",IF(G9>60,"逾期",IF(G9>30,"即将到期","正常")))
A10: 瑞丰金属 | B10: 0 | C10: =SUMIFS(加工订单!K:K,加工订单!C:C,A10,加工订单!A:A,">="&DATE(YEAR(TODAY()),MONTH(TODAY()),1)) | D10: =SUMIFS(收款记录!D:D,收款记录!C:C,A10,收款记录!A:A,">="&DATE(YEAR(TODAY()),MONTH(TODAY()),1)) | E10: =B10+C10-D10 | F10: =MAX(IF(加工订单!C:C=A10,加工订单!A:A),IF(收款记录!C:C=A10,收款记录!A:A)) | G10: =IF(F10=0,0,TODAY()-F10) | H10: =IF(G10>90,"严重逾期",IF(G10>60,"逾期",IF(G10>30,"即将到期","正常")))
A11: 合计 | B11: =SUM(B3:B10) | C11: =SUM(C3:C10) | D11: =SUM(D3:D10) | E11: =SUM(E3:E10) | F11: =SUM(F3:F10) | G11: =SUM(G3:G10) | H11: =SUM(H3:H10)
A13: 【客户明细对账】
A14: 【永达五金厂 对账明细】
A15: 日期 | B15: 单据类型 | C15: 单据号 | D15: 摘要 | E15: 应收金额 | F15: 已收金额 | G15: 余额
G16: =E16-F16
G17: =G16+E17-F17
G18: =G17+E18-F18
G19: =G18+E19-F19
G20: =G19+E20-F20
A21: 小计 | E21: =SUM(E16:E20) | F21: =SUM(F16:F20) | G21: =E21-F21
A23: 【恒丰铝业 对账明细】
A24: 日期 | B24: 单据类型 | C24: 单据号 | D24: 摘要 | E24: 应收金额 | F24: 已收金额 | G24: 余额
G25: =E25-F25
G26: =G25+E26-F26
G27: =G26+E27-F27
G28: =G27+E28-F28
G29: =G28+E29-F29
A30: 小计 | E30: =SUM(E25:E29) | F30: =SUM(F25:F29) | G30: =E30-F30
A32: 【鑫达精密 对账明细】
A33: 日期 | B33: 单据类型 | C33: 单据号 | D33: 摘要 | E33: 应收金额 | F33: 已收金额 | G33: 余额
G34: =E34-F34
G35: =G34+E35-F35
G36: =G35+E36-F36
G37: =G36+E37-F37
G38: =G37+E38-F38
A39: 小计 | E39: =SUM(E34:E38) | F39: =SUM(F34:F38) | G39: =E39-F39
A41: 【应付账款汇总 - 我方欠供应商】
A42: 供应商名称 | B42: 期初余额 | C42: 本月新增应付 | D42: 本月支付 | E42: 期末余额 | F42: 最后交易日期 | G42: 账龄(天) | H42: 状态
A43: XX化工 | B43: 0 | C43: =SUMIFS(付款记录!D:D,付款记录!C:C,A43,付款记录!A:A,">="&DATE(YEAR(TODAY()),MONTH(TODAY()),1)) | D43: =SUMIFS(付款记录!D:D,付款记录!C:C,A43,付款记录!A:A,">="&DATE(YEAR(TODAY()),MONTH(TODAY()),1)) | E43: =B43+C43-D43 | F43: =MAX(IF(付款记录!C:C=A43,付款记录!A:A)) | G43: =IF(F43=0,0,TODAY()-F43) | H43: =IF(G43>90,"严重逾期",IF(G43>60,"逾期",IF(G43>30,"即将到期","正常")))
A44: YY化工 | B44: 0 | C44: =SUMIFS(付款记录!D:D,付款记录!C:C,A44,付款记录!A:A,">="&DATE(YEAR(TODAY()),MONTH(TODAY()),1)) | D44: =SUMIFS(付款记录!D:D,付款记录!C:C,A44,付款记录!A:A,">="&DATE(YEAR(TODAY()),MONTH(TODAY()),1)) | E44: =B44+C44-D44 | F44: =MAX(IF(付款记录!C:C=A44,付款记录!A:A)) | G44: =IF(F44=0,0,TODAY()-F44) | H44: =IF(G44>90,"严重逾期",IF(G44>60,"逾期",IF(G44>30,"即将到期","正常")))
...

Sheet 会计凭证
A1: 会计凭证
A3: 凭证日期 | B3: 凭证字号 | C3: 摘要 | D3: 科目代码 | E3: 科目名称 | F3: 借方金额 | G3: 贷方金额 | H3: 附件张数
A4: 2024-01-15 | B4: 记-001 | C4: 销售氧化加工产品 | D4: 1122 | E4: 应收账款-客户A | F4: 11300 | G4: 0 | H4: 2
A5: 2024-01-15 | B5: 记-001 | C5: 销售氧化加工产品 | D5: 6001 | E5: 主营业务收入 | F5: 0 | G5: 10000 | H5: 2
A6: 2024-01-15 | B6: 记-001 | C6: 销售氧化加工产品 | D6: 2221 | E6: 应交税费-应交增值税 | F6: 0 | G6: 1300 | H6: 2
A7: 2024-01-16 | B7: 记-002 | C7: 收到客户A货款 | D7: 1002 | E7: 银行存款-G银行 | F7: 11300 | G7: 0 | H7: 1
A8: 2024-01-16 | B8: 记-002 | C8: 收到客户A货款 | D8: 1122 | E8: 应收账款-客户A | F8: 0 | G8: 11300 | H8: 1
A10: 说明：
A11: 1. 凭证字号格式：记-XXX（记账凭证）
A12: 2. 科目代码遵循小企业会计准则科目表
A13: 3. 借方金额+贷方金额必须相等（借贷平衡）
A14: 4. 可通过VBA宏从业务单据自动生成凭证

Sheet 银行对账
A1: 银行对账
A3: G银行对公账户对账
A4: 对账日期 | B4: 银行流水号 | C4: 对方户名 | D4: 收入金额 | E4: 支出金额 | F4: 余额 | G4: 系统匹配 | H4: 匹配状态 | I4: 差异说明 | J4: 对账标记 | K4: 对账人 | L4: 对账时间
A5: 2024-01-15 | B5: BX20240115001 | C5: 客户A | D5: 11300 | E5: 0 | F5: 51300 | G5: SK20240115001 | H5: 已匹配 | J5: √ | K5: 张会计 | L5: 2024-01-16
A6: 2024-01-15 | B6: BX20240115002 | C6: 硫酸供应商 | D6: 0 | E6: 5000 | F6: 46300 | G6: FK20240115002 | H6: 已匹配 | J6: √ | K6: 张会计 | L6: 2024-01-16
A7: 2024-01-16 | B7: BX20240116001 | C7: 客户B | D7: 5600 | E7: 0 | F7: 51900 | H7: 未匹配 | I7: 待核实
A8: 2024-01-16 | B8: BX20240116002 | C8: 手续费 | D8: 0 | E8: 15 | F8: 51885 | H8: 未匹配 | I8: 银行手续费
A11: N银行/微信账户对账
A12: 对账日期 | B12: 银行流水号 | C12: 对方户名 | D12: 收入金额 | E12: 支出金额 | F12: 余额 | G12: 系统匹配 | H12: 匹配状态 | I12: 差异说明 | J12: 对账标记 | K12: 对账人 | L12: 对账时间
A18: 说明：
A19: 1. 从网银导出Excel流水，使用VBA宏批量导入
A20: 2. 系统自动匹配系统内的收付款记录
A21: 3. 未匹配项需人工核实原因（可能是手续费、利息等）
A22: 4. 对账完成后生成银行余额调节表

Sheet 订单成本分析
A1: 订单成本利润分析
A3: 订单号 | B3: 客户名称 | C3: 产品名称 | D3: 加工数量 | E3: 单位 | F3: 加工收入 | G3: 材料成本 | H3: 人工成本 | I3: 制造费用 | J3: 成本合计 | K3: 订单毛利 | L3: 毛利率 | M3: 盈亏状态
A4: DD202401001 | B4: 客户A | C4: 铝件氧化 | D4: 1000 | E4: 件 | F4: 5000 | G4: 800 | H4: 1200 | I4: 400 | J4: 2400 | K4: 2600 | L4: 52.0% | M4: 盈利
A5: DD202401002 | B5: 客户B | C5: 不锈钢拉丝 | D5: 500 | E5: 件 | F5: 3500 | G5: 600 | H5: 900 | I5: 300 | J5: 1800 | K5: 1700 | L5: 48.6% | M5: 盈利
A6: DD202401003 | B6: 客户C | C6: 小件抛光 | D6: 200 | E6: 件 | F6: 400 | G6: 150 | H6: 300 | I6: 100 | J6: 550 | K6: -150 | L6: -37.5% | M6: 亏损
A8: 成本构成说明：
A9: 材料成本 = 直接材料（三酸、色粉等）
A10: 人工成本 = 工序工时 × 人工费率
A11: 制造费用 = 水电费、折旧等分摊
A12: 订单毛利 = 加工收入 - 材料成本 - 人工成本 - 制造费用
A13: 毛利率 = 订单毛利 ÷ 加工收入 × 100%

Sheet 财务仪表盘
A1: 财务分析仪表盘
A3: 一、资金状况 | H3: 四、关键财务指标
A4: 账户 | B4: 期初余额 | C4: 本期收入 | D4: 本期支出 | E4: 期末余额 | F4: 可用资金 | H4: 指标 | I4: 本月 | J4: 上月 | K4: 同比 | L4: 目标
A5: G银行（对公） | B5: 40000 | C5: 25000 | D5: 15000 | E5: 50000 | F5: 50000 | H5: 营业收入 | I5: 63000 | J5: 58000 | K5: +8.6% | L5: 60000
A6: N银行/微信（现金） | B6: 15000 | C6: 8000 | D6: 5000 | E6: 18000 | F6: 18000 | H6: 毛利率 | I6: 46.7% | J6: 45.2% | K6: +1.5% | L6: 45%
A7: 合计 | B7: 55000 | C7: 33000 | D7: 20000 | E7: 68000 | F7: 68000 | H7: 净利率 | I7: 32.1% | J7: 30.5% | K7: +1.6% | L7: 30%
H8: 应收账款周转天数 | I8: 15 | J8: 18 | K8: -3天 | L8: 20天
H9: 人均产值 | I9: 12600 | J9: 11600 | K9: +8.6% | L9: 12000
A10: 二、应收应付结构
A11: 项目 | B11: 金额 | C11: 占比 | D11: 账龄 | E11: 风险等级
A12: 应收账款 | B12: 15000 | C12: 22.1% | D12: 30天内 | E12: 正常
A13: 其中：逾期应收 | B13: 3000 | C13: 4.4% | D13: 60天以上 | E13: 关注
A14: 应付账款 | B14: 8000 | C14: 11.8% | D14: 30天内 | E14: 正常
A15: 资金净额 | B15: 7000 | C15: 10.3% | D15: - | E15: -
A17: 三、本月收入成本趋势
A18: 日期 | B18: 加工收入 | C18: 材料成本 | D18: 人工成本 | E18: 费用 | F18: 毛利 | G18: 毛利率
A19: 1-5日 | B19: 8000 | C19: 1500 | D19: 2000 | E19: 800 | F19: 3700 | G19: 46.3%
A20: 6-10日 | B20: 12000 | C20: 2200 | D20: 3000 | E20: 1200 | F20: 5600 | G20: 46.7%
A21: 11-15日 | B21: 15000 | C21: 2800 | D21: 3800 | E21: 1500 | F21: 6900 | G21: 46.0%
